

//
// Source code recreated from a .class file by IntelliJ IDEA
// (powered by Fernflower decompiler)
//

package thaumcraft.common.lib.world;

import java.util.Random;
import net.minecraft.block.Block;
import net.minecraft.init.Blocks;
import net.minecraft.tileentity.TileEntityChest;
import net.minecraft.tileentity.TileEntityMobSpawner;
import net.minecraft.util.WeightedRandomChestContent;
import net.minecraft.world.World;
import net.minecraft.world.gen.feature.WorldGenerator;
import net.minecraftforge.common.ChestGenHooks;
import thaumcraft.common.config.ConfigBlocks;

public class WorldGenMound extends WorldGenerator {
    public WorldGenMound() {
    }

    protected Block[] GetValidSpawnBlocks() {
        return new Block[]{Blocks.stone, Blocks.grass, Blocks.dirt};
    }

    public boolean LocationIsValidSpawn(World world, int i, int j, int k) {
        int distanceToAir = 0;

        for(Block checkID = world.getBlock(i, j, k); checkID != Blocks.air; checkID = world.getBlock(i, j + distanceToAir, k)) {
            ++distanceToAir;
        }

        if(distanceToAir > 2) {
            return false;
        } else {
            j += distanceToAir - 1;
            Block blockID = world.getBlock(i, j, k);
            Block blockIDAbove = world.getBlock(i, j + 1, k);
            Block blockIDBelow = world.getBlock(i, j - 1, k);
            Block[] arr$ = this.GetValidSpawnBlocks();
            int len$ = arr$.length;

            for(int i$ = 0; i$ < len$; ++i$) {
                Block x = arr$[i$];
                if(blockIDAbove != Blocks.air) {
                    return false;
                }

                if(blockID == x) {
                    return true;
                }

                if((blockID == Blocks.snow_layer || blockID == Blocks.tallgrass) && blockIDBelow == x) {
                    return true;
                }
            }

            return false;
        }
    }

    public boolean generate(World world, Random rand, int i, int j, int k) {
        if(this.LocationIsValidSpawn(world, i + 9, j + 9, k + 9) && this.LocationIsValidSpawn(world, i, j + 9, k) && this.LocationIsValidSpawn(world, i + 18, j + 9, k) && this.LocationIsValidSpawn(world, i + 18, j + 9, k + 18) && this.LocationIsValidSpawn(world, i, j + 9, k + 18)) {

            world.setBlock(i + 2 , j + 11, k + 9 , Blocks.stonebrick  , 3, 3);

            world.setBlock(i + 14, j + 8 , k + 12, Blocks.mossy_cobblestone) ;
            world.setBlock(i + 8 , j + 8 , k + 5 , Blocks.mossy_cobblestone) ;
            world.setBlock(i + 2 , j + 10, k + 10, Blocks.mossy_cobblestone) ;
            world.setBlock(i + 3 , j + 5 , k + 7 , Blocks.mossy_cobblestone) ;
            world.setBlock(i + 3 , j + 6 , k + 13, Blocks.mossy_cobblestone) ;
            world.setBlock(i + 3 , j + 8 , k + 7 , Blocks.mossy_cobblestone) ;
            world.setBlock(i + 6 , j + 5 , k + 6 , Blocks.mossy_cobblestone) ;
            world.setBlock(i + 11, j + 9 , k + 12, Blocks.mossy_cobblestone) ;
            world.setBlock(i + 12, j + 12, k + 6 , Blocks.mossy_cobblestone) ;
            world.setBlock(i + 14, j + 6 , k + 5 , Blocks.mossy_cobblestone) ;
            world.setBlock(i + 5 , j + 6 , k + 3 , Blocks.mossy_cobblestone) ;
            world.setBlock(i + 12, j + 8 , k + 4 , Blocks.mossy_cobblestone) ;
            world.setBlock(i + 5 , j + 8 , k + 4 , Blocks.mossy_cobblestone) ;
            world.setBlock(i + 11, j + 6 , k + 3 , Blocks.mossy_cobblestone) ;
            world.setBlock(i + 8 , j + 4 , k + 5 , Blocks.mossy_cobblestone) ;
            world.setBlock(i + 8 , j + 6 , k + 3 , Blocks.mossy_cobblestone) ;
            world.setBlock(i + 13, j + 10, k + 3 , Blocks.mossy_cobblestone) ;
            world.setBlock(i + 6 , j + 1 , k + 6 , Blocks.mossy_cobblestone) ;
            world.setBlock(i + 9 , j + 0 , k + 8 , Blocks.mossy_cobblestone) ;
            world.setBlock(i + 10, j + 0 , k + 7 , Blocks.mossy_cobblestone) ;
            world.setBlock(i + 5 , j + 8 , k + 13, Blocks.mossy_cobblestone) ;
            world.setBlock(i + 15, j + 7 , k + 11, Blocks.mossy_cobblestone) ;
            world.setBlock(i + 15, j + 9 , k + 7 , Blocks.mossy_cobblestone) ;
            world.setBlock(i + 11, j + 7 , k + 12, Blocks.mossy_cobblestone) ;
            world.setBlock(i + 12, j + 12, k + 11, Blocks.mossy_cobblestone) ;
            world.setBlock(i + 7 , j + 12, k + 9 , Blocks.mossy_cobblestone) ;
            world.setBlock(i + 8 , j + 12, k + 7 , Blocks.mossy_cobblestone) ;
            world.setBlock(i + 12, j + 1 , k + 11, Blocks.mossy_cobblestone) ;
            world.setBlock(i + 7 , j + 1 , k + 6 , Blocks.mossy_cobblestone) ;
            world.setBlock(i + 6 , j + 12, k + 6 , Blocks.mossy_cobblestone) ;
            world.setBlock(i + 11, j + 10, k + 12, Blocks.mossy_cobblestone) ;
            world.setBlock(i + 6 , j + 1 , k + 9 , Blocks.mossy_cobblestone) ;
            world.setBlock(i + 12, j + 8 , k + 7 , Blocks.mossy_cobblestone) ;
            world.setBlock(i + 9 , j + 0 , k + 11, Blocks.mossy_cobblestone) ;
            world.setBlock(i + 3 , j + 10, k + 4 , Blocks.mossy_cobblestone) ;
            world.setBlock(i + 9 , j + 3 , k + 12, Blocks.mossy_cobblestone) ;
            world.setBlock(i + 6 , j + 10, k + 12, Blocks.mossy_cobblestone) ;
            world.setBlock(i + 14, j + 6 , k + 15, Blocks.mossy_cobblestone) ;
            world.setBlock(i + 9 , j + 9 , k + 15, Blocks.mossy_cobblestone) ;
            world.setBlock(i + 9 , j + 12, k + 7 , Blocks.mossy_cobblestone) ;
            world.setBlock(i + 9 , j + 10, k + 3 , Blocks.mossy_cobblestone) ;
            world.setBlock(i + 14, j + 4 , k + 14, Blocks.mossy_cobblestone) ;
            world.setBlock(i + 4 , j + 7 , k + 3 , Blocks.mossy_cobblestone) ;
            world.setBlock(i + 6 , j + 9 , k + 6 , Blocks.mossy_cobblestone) ;
            world.setBlock(i + 6 , j + 11, k + 15, Blocks.mossy_cobblestone) ;
            world.setBlock(i + 7 , j + 0 , k + 11, Blocks.mossy_cobblestone) ;
            world.setBlock(i + 15, j + 10, k + 14, Blocks.mossy_cobblestone) ;
            world.setBlock(i + 10, j + 12, k + 12, Blocks.mossy_cobblestone) ;
            world.setBlock(i + 2 , j + 8 , k + 9 , Blocks.mossy_cobblestone) ;
            world.setBlock(i + 12, j + 1 , k + 6 , Blocks.mossy_cobblestone) ;
            world.setBlock(i + 3 , j + 7 , k + 11, Blocks.mossy_cobblestone) ;
            world.setBlock(i + 11, j + 2 , k + 10, Blocks.mossy_cobblestone) ;
            world.setBlock(i + 10, j + 12, k + 9 , Blocks.mossy_cobblestone) ;
            world.setBlock(i + 12, j + 4 , k + 8 , Blocks.mossy_cobblestone) ;
            world.setBlock(i + 15, j + 10, k + 5 , Blocks.mossy_cobblestone) ;
            world.setBlock(i + 6 , j + 12, k + 9 , Blocks.mossy_cobblestone) ;
            world.setBlock(i + 3 , j + 10, k + 7 , Blocks.mossy_cobblestone) ;
            world.setBlock(i + 9 , j + 10, k + 15, Blocks.mossy_cobblestone) ;
            world.setBlock(i + 6 , j + 5 , k + 15, Blocks.mossy_cobblestone) ;
            world.setBlock(i + 6 , j + 3 , k + 8 , Blocks.mossy_cobblestone) ;
            world.setBlock(i + 5 , j + 12, k + 12, Blocks.mossy_cobblestone) ;
            world.setBlock(i + 5 , j + 4 , k + 13, Blocks.mossy_cobblestone) ;
            world.setBlock(i + 4 , j + 11, k + 14, Blocks.mossy_cobblestone) ;
            world.setBlock(i + 4 , j + 8 , k + 9 , Blocks.mossy_cobblestone) ;
            world.setBlock(i + 9 , j + 1 , k + 12, Blocks.mossy_cobblestone) ;
            world.setBlock(i + 3 , j + 10, k + 5 , Blocks.mossy_cobblestone) ;
            world.setBlock(i + 3 , j + 11, k + 9 , Blocks.mossy_cobblestone) ;
            world.setBlock(i + 15, j + 10, k + 10, Blocks.mossy_cobblestone) ;
            world.setBlock(i + 11, j + 6 , k + 6 , Blocks.mossy_cobblestone) ;
            world.setBlock(i + 11, j + 11, k + 3 , Blocks.mossy_cobblestone) ;
            world.setBlock(i + 9 , j + 0 , k + 10, Blocks.mossy_cobblestone) ;
            world.setBlock(i + 4 , j + 8 , k + 10, Blocks.mossy_cobblestone) ;
            world.setBlock(i + 4 , j + 10, k + 15, Blocks.mossy_cobblestone) ;
            world.setBlock(i + 9 , j + 8 , k + 13, Blocks.mossy_cobblestone) ;
            world.setBlock(i + 12, j + 8 , k + 14, Blocks.mossy_cobblestone) ;
            world.setBlock(i + 11, j + 10, k + 15, Blocks.mossy_cobblestone) ;
            world.setBlock(i + 15, j + 6 , k + 10, Blocks.mossy_cobblestone) ;
            world.setBlock(i + 5 , j + 4 , k + 10, Blocks.mossy_cobblestone) ;
            world.setBlock(i + 6 , j + 1 , k + 10, Blocks.mossy_cobblestone) ;
            world.setBlock(i + 14, j + 8 , k + 11, Blocks.mossy_cobblestone) ;
            world.setBlock(i + 6 , j + 6 , k + 6 , Blocks.mossy_cobblestone) ;
            world.setBlock(i + 4 , j + 8 , k + 5 , Blocks.mossy_cobblestone) ;
            world.setBlock(i + 12, j + 8 , k + 8 , Blocks.mossy_cobblestone) ;
            world.setBlock(i + 10, j + 4 , k + 4 , Blocks.mossy_cobblestone) ;
            world.setBlock(i + 3 , j + 9 , k + 12, Blocks.mossy_cobblestone) ;
            world.setBlock(i + 10, j + 8 , k + 4 , Blocks.mossy_cobblestone) ;
            world.setBlock(i + 7 , j + 0 , k + 10, Blocks.mossy_cobblestone) ;
            world.setBlock(i + 7 , j + 0 , k + 7 , Blocks.mossy_cobblestone) ;
            world.setBlock(i + 12, j + 4 , k + 13, Blocks.mossy_cobblestone) ;
            world.setBlock(i + 7 , j + 6 , k + 15, Blocks.mossy_cobblestone) ;
            world.setBlock(i + 15, j + 10, k + 11, Blocks.mossy_cobblestone) ;
            world.setBlock(i + 7 , j + 11, k + 3 , Blocks.mossy_cobblestone) ;
            world.setBlock(i + 8 , j + 1 , k + 12, Blocks.mossy_cobblestone) ;
            world.setBlock(i + 11, j + 0 , k + 10, Blocks.mossy_cobblestone) ;
            world.setBlock(i + 8 , j + 10, k + 3 , Blocks.mossy_cobblestone) ;
            world.setBlock(i + 2 , j + 11, k + 10, Blocks.mossy_cobblestone) ;
            world.setBlock(i + 12, j + 1 , k + 9 , Blocks.mossy_cobblestone) ;
            world.setBlock(i + 3 , j + 5 , k + 8 , Blocks.mossy_cobblestone) ;
            world.setBlock(i + 8 , j + 10, k + 15, Blocks.mossy_cobblestone) ;
            world.setBlock(i + 11, j + 3 , k + 9 , Blocks.mossy_cobblestone) ;
            world.setBlock(i + 13, j + 8 , k + 14, Blocks.mossy_cobblestone) ;
            world.setBlock(i + 13, j + 8 , k + 11, Blocks.mossy_cobblestone) ;
            world.setBlock(i + 13, j + 4 , k + 8 , Blocks.mossy_cobblestone) ;
            world.setBlock(i + 7 , j + 8 , k + 14, Blocks.mossy_cobblestone) ;
            world.setBlock(i + 15, j + 10, k + 8 , Blocks.mossy_cobblestone) ;
            world.setBlock(i + 9 , j + 1 , k + 6 , Blocks.mossy_cobblestone) ;
            world.setBlock(i + 15, j + 11, k + 5 , Blocks.mossy_cobblestone) ;
            world.setBlock(i + 15, j + 11, k + 10, Blocks.mossy_cobblestone) ;
            world.setBlock(i + 10, j + 6 , k + 15, Blocks.mossy_cobblestone) ;
            world.setBlock(i + 12, j + 1 , k + 12, Blocks.mossy_cobblestone) ;
            world.setBlock(i + 6 , j + 8 , k + 12, Blocks.mossy_cobblestone) ;
            world.setBlock(i + 10, j + 0 , k + 11, Blocks.mossy_cobblestone) ;
            world.setBlock(i + 4 , j + 8 , k + 4 , Blocks.mossy_cobblestone) ;
            world.setBlock(i + 10, j + 0 , k + 8 , Blocks.mossy_cobblestone) ;

            world.setBlock(i + 3 , j + 10, k + 9 , Blocks.iron_bars)         ;
            world.setBlock(i + 3 , j + 9 , k + 9 , Blocks.iron_bars)         ;


            world.setBlock(i + 4 , j + 8 , k + 3 , Blocks.cobblestone)       ;
            world.setBlock(i + 15, j + 11, k + 13, Blocks.cobblestone)       ;
            world.setBlock(i + 15, j + 11, k + 12, Blocks.cobblestone)       ;
            world.setBlock(i + 15, j + 11, k + 11, Blocks.cobblestone)       ;
            world.setBlock(i + 15, j + 11, k + 9 , Blocks.cobblestone)       ;
            world.setBlock(i + 10, j + 0 , k + 9 , Blocks.cobblestone)       ;
            world.setBlock(i + 15, j + 11, k + 7 , Blocks.cobblestone)       ;
            world.setBlock(i + 15, j + 11, k + 6 , Blocks.cobblestone)       ;
            world.setBlock(i + 15, j + 10, k + 15, Blocks.cobblestone)       ;
            world.setBlock(i + 15, j + 10, k + 13, Blocks.cobblestone)       ;
            world.setBlock(i + 0 , j + 8 , k + 8 , Blocks.cobblestone)       ;
            world.setBlock(i + 0 , j + 8 , k + 9 , Blocks.cobblestone)       ;
            world.setBlock(i + 0 , j + 8 , k + 10, Blocks.cobblestone)       ;
            world.setBlock(i + 15, j + 10, k + 12, Blocks.cobblestone)       ;
            world.setBlock(i + 9 , j + 8 , k + 15, Blocks.cobblestone)       ;
            world.setBlock(i + 5 , j + 8 , k + 12, Blocks.cobblestone)       ;
            world.setBlock(i + 9 , j + 12, k + 11, Blocks.cobblestone)       ;
            world.setBlock(i + 10, j + 12, k + 5 , Blocks.cobblestone)       ;
            world.setBlock(i + 13, j + 7 , k + 15, Blocks.cobblestone)       ;
            world.setBlock(i + 9 , j + 0 , k + 9 , Blocks.cobblestone)       ;
            world.setBlock(i + 10, j + 1 , k + 6 , Blocks.cobblestone)       ;
            world.setBlock(i + 9 , j + 12, k + 12, Blocks.cobblestone)       ;
            world.setBlock(i + 9 , j + 12, k + 4 , Blocks.cobblestone)       ;
            world.setBlock(i + 10, j + 12, k + 4 , Blocks.cobblestone)       ;
            world.setBlock(i + 9 , j + 7 , k + 3 , Blocks.cobblestone)       ;
            world.setBlock(i + 10, j + 12, k + 13, Blocks.cobblestone)       ;
            world.setBlock(i + 9 , j + 2 , k + 12, Blocks.cobblestone)       ;
            world.setBlock(i + 11, j + 0 , k + 9 , Blocks.cobblestone)       ;
            world.setBlock(i + 15, j + 10, k + 7 , Blocks.cobblestone)       ;
            world.setBlock(i + 10, j + 0 , k + 12, Blocks.cobblestone)       ;
            world.setBlock(i + 5 , j + 12, k + 14, Blocks.cobblestone)       ;
            world.setBlock(i + 9 , j + 12, k + 13, Blocks.cobblestone)       ;
            world.setBlock(i + 9 , j + 12, k + 9 , Blocks.cobblestone)       ;
            world.setBlock(i + 9 , j + 12, k + 5 , Blocks.cobblestone)       ;
            world.setBlock(i + 10, j + 8 , k + 5 , Blocks.cobblestone)       ;
            world.setBlock(i + 10, j + 11, k + 15, Blocks.cobblestone)       ;
            world.setBlock(i + 10, j + 12, k + 10, Blocks.cobblestone)       ;
            world.setBlock(i + 9 , j + 7 , k + 15, Blocks.cobblestone)       ;
            world.setBlock(i + 9 , j + 4 , k + 14, Blocks.cobblestone)       ;
            world.setBlock(i + 9 , j + 4 , k + 13, Blocks.cobblestone)       ;
            world.setBlock(i + 15, j + 9 , k + 8 , Blocks.cobblestone)       ;
            world.setBlock(i + 9 , j + 3 , k + 6 , Blocks.cobblestone)       ;
            world.setBlock(i + 11, j + 0 , k + 6 , Blocks.cobblestone)       ;
            world.setBlock(i + 11, j + 0 , k + 8 , Blocks.cobblestone)       ;
            world.setBlock(i + 15, j + 8 , k + 8 , Blocks.cobblestone)       ;
            world.setBlock(i + 15, j + 10, k + 4 , Blocks.cobblestone)       ;
            world.setBlock(i + 15, j + 10, k + 9 , Blocks.cobblestone)       ;
            world.setBlock(i + 10, j + 0 , k + 10, Blocks.cobblestone)       ;
            world.setBlock(i + 10, j + 4 , k + 3 , Blocks.cobblestone)       ;
            world.setBlock(i + 10, j + 4 , k + 13, Blocks.cobblestone)       ;
            world.setBlock(i + 10, j + 5 , k + 3 , Blocks.cobblestone)       ;
            world.setBlock(i + 9 , j + 12, k + 14, Blocks.cobblestone)       ;
            world.setBlock(i + 15, j + 9 , k + 12, Blocks.cobblestone)       ;
            world.setBlock(i + 9 , j + 12, k + 10, Blocks.cobblestone)       ;
            world.setBlock(i + 9 , j + 12, k + 8 , Blocks.cobblestone)       ;
            world.setBlock(i + 9 , j + 12, k + 6 , Blocks.cobblestone)       ;
            world.setBlock(i + 9 , j + 11, k + 3 , Blocks.cobblestone)       ;
            world.setBlock(i + 10, j + 8 , k + 3 , Blocks.cobblestone)       ;
            world.setBlock(i + 10, j + 8 , k + 15, Blocks.cobblestone)       ;
            world.setBlock(i + 10, j + 11, k + 3 , Blocks.cobblestone)       ;
            world.setBlock(i + 10, j + 12, k + 6 , Blocks.cobblestone)       ;
            world.setBlock(i + 10, j + 12, k + 8 , Blocks.cobblestone)       ;
            world.setBlock(i + 1 , j + 8 , k + 10, Blocks.cobblestone)       ;
            world.setBlock(i + 10, j + 12, k + 11, Blocks.cobblestone)       ;
            world.setBlock(i + 9 , j + 5 , k + 15, Blocks.cobblestone)       ;
            world.setBlock(i + 9 , j + 4 , k + 15, Blocks.cobblestone)       ;
            world.setBlock(i + 15, j + 8 , k + 13, Blocks.cobblestone)       ;
            world.setBlock(i + 15, j + 7 , k + 13, Blocks.cobblestone)       ;
            world.setBlock(i + 15, j + 7 , k + 12, Blocks.cobblestone)       ;
            world.setBlock(i + 15, j + 8 , k + 12, Blocks.cobblestone)       ;
            world.setBlock(i + 15, j + 9 , k + 14, Blocks.cobblestone)       ;
            world.setBlock(i + 10, j + 12, k + 14, Blocks.cobblestone)       ;
            world.setBlock(i + 9 , j + 2 , k + 6 , Blocks.cobblestone)       ;
            world.setBlock(i + 15, j + 7 , k + 9 , Blocks.cobblestone)       ;
            world.setBlock(i + 15, j + 7 , k + 8 , Blocks.cobblestone)       ;
            world.setBlock(i + 9 , j + 0 , k + 12, Blocks.cobblestone)       ;
            world.setBlock(i + 15, j + 7 , k + 6 , Blocks.cobblestone)       ;
            world.setBlock(i + 2 , j + 8 , k + 7 , Blocks.cobblestone)       ;
            world.setBlock(i + 2 , j + 8 , k + 8 , Blocks.cobblestone)       ;
            world.setBlock(i + 15, j + 9 , k + 13, Blocks.cobblestone)       ;
            world.setBlock(i + 2 , j + 8 , k + 10, Blocks.cobblestone)       ;
            world.setBlock(i + 2 , j + 8 , k + 11, Blocks.cobblestone)       ;
            world.setBlock(i + 15, j + 7 , k + 5 , Blocks.cobblestone)       ;
            world.setBlock(i + 15, j + 7 , k + 4 , Blocks.cobblestone)       ;
            world.setBlock(i + 10, j + 2 , k + 6 , Blocks.cobblestone)       ;
            world.setBlock(i + 10, j + 3 , k + 12, Blocks.cobblestone)       ;
            world.setBlock(i + 13, j + 4 , k + 13, Blocks.cobblestone)       ;
            world.setBlock(i + 10, j + 4 , k + 5 , Blocks.cobblestone)       ;
            world.setBlock(i + 15, j + 9 , k + 5 , Blocks.cobblestone)       ;
            world.setBlock(i + 10, j + 4 , k + 15, Blocks.cobblestone)       ;
            world.setBlock(i + 15, j + 8 , k + 7 , Blocks.cobblestone)       ;
            world.setBlock(i + 10, j + 5 , k + 15, Blocks.cobblestone)       ;
            world.setBlock(i + 15, j + 9 , k + 4 , Blocks.cobblestone)       ;
            world.setBlock(i + 2 , j + 9 , k + 8 , Blocks.cobblestone)       ;
            world.setBlock(i + 15, j + 10, k + 3 , Blocks.cobblestone)       ;
            world.setBlock(i + 2 , j + 9 , k + 10, Blocks.cobblestone)       ;
            world.setBlock(i + 15, j + 9 , k + 3 , Blocks.cobblestone)       ;
            world.setBlock(i + 15, j + 6 , k + 6 , Blocks.cobblestone)       ;
            world.setBlock(i + 10, j + 6 , k + 3 , Blocks.cobblestone)       ;
            world.setBlock(i + 15, j + 6 , k + 4 , Blocks.cobblestone)       ;
            world.setBlock(i + 10, j + 7 , k + 3 , Blocks.cobblestone)       ;
            world.setBlock(i + 9 , j + 11, k + 15, Blocks.cobblestone)       ;
            world.setBlock(i + 15, j + 5 , k + 15, Blocks.cobblestone)       ;
            world.setBlock(i + 1 , j + 8 , k + 9 , Blocks.cobblestone)       ;
            world.setBlock(i + 3 , j + 9 , k + 3 , Blocks.cobblestone)       ;
            world.setBlock(i + 10, j + 8 , k + 14, Blocks.cobblestone)       ;
            world.setBlock(i + 13, j + 4 , k + 14, Blocks.cobblestone)       ;
            world.setBlock(i + 10, j + 10, k + 15, Blocks.cobblestone)       ;
            world.setBlock(i + 9 , j + 8 , k + 14, Blocks.cobblestone)       ;
            world.setBlock(i + 15, j + 5 , k + 11, Blocks.cobblestone)       ;
            world.setBlock(i + 9 , j + 8 , k + 5 , Blocks.cobblestone)       ;
            world.setBlock(i + 9 , j + 8 , k + 3 , Blocks.cobblestone)       ;
            world.setBlock(i + 15, j + 7 , k + 15, Blocks.cobblestone)       ;
            world.setBlock(i + 15, j + 5 , k + 9 , Blocks.cobblestone)       ;
            world.setBlock(i + 15, j + 5 , k + 8 , Blocks.cobblestone)       ;
            world.setBlock(i + 15, j + 5 , k + 7 , Blocks.cobblestone)       ;
            world.setBlock(i + 15, j + 9 , k + 9 , Blocks.cobblestone)       ;
            world.setBlock(i + 9 , j + 6 , k + 3 , Blocks.cobblestone)       ;
            world.setBlock(i + 9 , j + 5 , k + 3 , Blocks.cobblestone)       ;
            world.setBlock(i + 2 , j + 11, k + 8 , Blocks.cobblestone)       ;
            world.setBlock(i + 15, j + 5 , k + 5 , Blocks.cobblestone)       ;
            world.setBlock(i + 15, j + 5 , k + 4 , Blocks.cobblestone)       ;
            world.setBlock(i + 15, j + 5 , k + 3 , Blocks.cobblestone)       ;
            world.setBlock(i + 15, j + 4 , k + 15, Blocks.cobblestone)       ;
            world.setBlock(i + 15, j + 4 , k + 14, Blocks.cobblestone)       ;
            world.setBlock(i + 15, j + 4 , k + 13, Blocks.cobblestone)       ;
            world.setBlock(i + 15, j + 4 , k + 12, Blocks.cobblestone)       ;
            world.setBlock(i + 15, j + 4 , k + 11, Blocks.cobblestone)       ;
            world.setBlock(i + 15, j + 4 , k + 10, Blocks.cobblestone)       ;
            world.setBlock(i + 15, j + 8 , k + 11, Blocks.cobblestone)       ;
            world.setBlock(i + 9 , j + 4 , k + 3 , Blocks.cobblestone)       ;
            world.setBlock(i + 15, j + 4 , k + 7 , Blocks.cobblestone)       ;
            world.setBlock(i + 15, j + 7 , k + 10, Blocks.cobblestone)       ;
            world.setBlock(i + 15, j + 8 , k + 10, Blocks.cobblestone)       ;
            world.setBlock(i + 3 , j + 4 , k + 5 , Blocks.cobblestone)       ;
            world.setBlock(i + 3 , j + 4 , k + 6 , Blocks.cobblestone)       ;
            world.setBlock(i + 3 , j + 4 , k + 7 , Blocks.cobblestone)       ;
            world.setBlock(i + 3 , j + 4 , k + 8 , Blocks.cobblestone)       ;
            world.setBlock(i + 11, j + 0 , k + 7 , Blocks.cobblestone)       ;
            world.setBlock(i + 3 , j + 4 , k + 10, Blocks.cobblestone)       ;
            world.setBlock(i + 3 , j + 4 , k + 11, Blocks.cobblestone)       ;
            world.setBlock(i + 3 , j + 4 , k + 12, Blocks.cobblestone)       ;
            world.setBlock(i + 3 , j + 4 , k + 13, Blocks.cobblestone)       ;
            world.setBlock(i + 3 , j + 4 , k + 14, Blocks.cobblestone)       ;
            world.setBlock(i + 3 , j + 4 , k + 15, Blocks.cobblestone)       ;
            world.setBlock(i + 3 , j + 5 , k + 3 , Blocks.cobblestone)       ;
            world.setBlock(i + 3 , j + 5 , k + 4 , Blocks.cobblestone)       ;
            world.setBlock(i + 3 , j + 5 , k + 5 , Blocks.cobblestone)       ;
            world.setBlock(i + 3 , j + 5 , k + 6 , Blocks.cobblestone)       ;
            world.setBlock(i + 15, j + 4 , k + 6 , Blocks.cobblestone)       ;
            world.setBlock(i + 15, j + 4 , k + 5 , Blocks.cobblestone)       ;
            world.setBlock(i + 3 , j + 5 , k + 9 , Blocks.cobblestone)       ;
            world.setBlock(i + 3 , j + 5 , k + 10, Blocks.cobblestone)       ;
            world.setBlock(i + 3 , j + 5 , k + 11, Blocks.cobblestone)       ;
            world.setBlock(i + 3 , j + 5 , k + 12, Blocks.cobblestone)       ;
            world.setBlock(i + 3 , j + 5 , k + 13, Blocks.cobblestone)       ;
            world.setBlock(i + 15, j + 7 , k + 3 , Blocks.cobblestone)       ;
            world.setBlock(i + 10, j + 1 , k + 12, Blocks.cobblestone)       ;
            world.setBlock(i + 10, j + 2 , k + 12, Blocks.cobblestone)       ;
            world.setBlock(i + 10, j + 3 , k + 6 , Blocks.cobblestone)       ;
            world.setBlock(i + 3 , j + 6 , k + 5 , Blocks.cobblestone)       ;
            world.setBlock(i + 15, j + 6 , k + 14, Blocks.cobblestone)       ;
            world.setBlock(i + 15, j + 6 , k + 13, Blocks.cobblestone)       ;
            world.setBlock(i + 3 , j + 6 , k + 8 , Blocks.cobblestone)       ;
            world.setBlock(i + 3 , j + 6 , k + 9 , Blocks.cobblestone)       ;
            world.setBlock(i + 1 , j + 9 , k + 10, Blocks.cobblestone)       ;
            world.setBlock(i + 5 , j + 12, k + 13, Blocks.cobblestone)       ;
            world.setBlock(i + 10, j + 4 , k + 14, Blocks.cobblestone)       ;
            world.setBlock(i + 15, j + 4 , k + 4 , Blocks.cobblestone)       ;
            world.setBlock(i + 15, j + 6 , k + 11, Blocks.cobblestone)       ;
            world.setBlock(i + 15, j + 6 , k + 9 , Blocks.cobblestone)       ;
            world.setBlock(i + 3 , j + 7 , k + 3 , Blocks.cobblestone)       ;
            world.setBlock(i + 15, j + 6 , k + 8 , Blocks.cobblestone)       ;
            world.setBlock(i + 3 , j + 7 , k + 5 , Blocks.cobblestone)       ;
            world.setBlock(i + 3 , j + 7 , k + 6 , Blocks.cobblestone)       ;
            world.setBlock(i + 3 , j + 7 , k + 7 , Blocks.cobblestone)       ;
            world.setBlock(i + 3 , j + 7 , k + 8 , Blocks.cobblestone)       ;
            world.setBlock(i + 3 , j + 7 , k + 9 , Blocks.cobblestone)       ;
            world.setBlock(i + 3 , j + 7 , k + 10, Blocks.cobblestone)       ;
            world.setBlock(i + 15, j + 4 , k + 3 , Blocks.cobblestone)       ;
            world.setBlock(i + 15, j + 8 , k + 6 , Blocks.cobblestone)       ;
            world.setBlock(i + 3 , j + 7 , k + 13, Blocks.cobblestone)       ;
            world.setBlock(i + 3 , j + 7 , k + 14, Blocks.cobblestone)       ;
            world.setBlock(i + 3 , j + 7 , k + 15, Blocks.cobblestone)       ;
            world.setBlock(i + 15, j + 8 , k + 5 , Blocks.cobblestone)       ;
            world.setBlock(i + 14, j + 12, k + 13, Blocks.cobblestone)       ;
            world.setBlock(i + 3 , j + 8 , k + 3 , Blocks.cobblestone)       ;
            world.setBlock(i + 3 , j + 8 , k + 4 , Blocks.cobblestone)       ;
            world.setBlock(i + 15, j + 6 , k + 3 , Blocks.cobblestone)       ;
            world.setBlock(i + 15, j + 9 , k + 11, Blocks.cobblestone)       ;
            world.setBlock(i + 5 , j + 12, k + 4 , Blocks.cobblestone)       ;
            world.setBlock(i + 3 , j + 8 , k + 8 , Blocks.cobblestone)       ;
            world.setBlock(i + 3 , j + 8 , k + 9 , Blocks.cobblestone)       ;
            world.setBlock(i + 3 , j + 8 , k + 10, Blocks.cobblestone)       ;
            world.setBlock(i + 15, j + 5 , k + 14, Blocks.cobblestone)       ;
            world.setBlock(i + 15, j + 8 , k + 3 , Blocks.cobblestone)       ;
            world.setBlock(i + 15, j + 5 , k + 13, Blocks.cobblestone)       ;
            world.setBlock(i + 1 , j + 8 , k + 8 , Blocks.cobblestone)       ;
            world.setBlock(i + 15, j + 5 , k + 12, Blocks.cobblestone)       ;
            world.setBlock(i + 10, j + 8 , k + 13, Blocks.cobblestone)       ;
            world.setBlock(i + 2 , j + 10, k + 8 , Blocks.cobblestone)       ;
            world.setBlock(i + 10, j + 9 , k + 15, Blocks.cobblestone)       ;
            world.setBlock(i + 10, j + 10, k + 3 , Blocks.cobblestone)       ;
            world.setBlock(i + 13, j + 4 , k + 15, Blocks.cobblestone)       ;
            world.setBlock(i + 15, j + 9 , k + 15, Blocks.cobblestone)       ;
            world.setBlock(i + 15, j + 10, k + 6 , Blocks.cobblestone)       ;
            world.setBlock(i + 3 , j + 9 , k + 6 , Blocks.cobblestone)       ;
            world.setBlock(i + 3 , j + 9 , k + 7 , Blocks.cobblestone)       ;
            world.setBlock(i + 3 , j + 9 , k + 8 , Blocks.cobblestone)       ;
            world.setBlock(i + 13, j + 5 , k + 15, Blocks.cobblestone)       ;
            world.setBlock(i + 9 , j + 8 , k + 4 , Blocks.cobblestone)       ;
            world.setBlock(i + 3 , j + 9 , k + 11, Blocks.cobblestone)       ;
            world.setBlock(i + 14, j + 12, k + 7 , Blocks.cobblestone)       ;
            world.setBlock(i + 3 , j + 9 , k + 13, Blocks.cobblestone)       ;
            world.setBlock(i + 3 , j + 9 , k + 14, Blocks.cobblestone)       ;
            world.setBlock(i + 3 , j + 9 , k + 15, Blocks.cobblestone)       ;
            world.setBlock(i + 14, j + 12, k + 6 , Blocks.cobblestone)       ;
            world.setBlock(i + 14, j + 12, k + 5 , Blocks.cobblestone)       ;
            world.setBlock(i + 14, j + 11, k + 14, Blocks.cobblestone)       ;
            world.setBlock(i + 3 , j + 10, k + 3 , Blocks.cobblestone)       ;
            world.setBlock(i + 15, j + 5 , k + 6 , Blocks.cobblestone)       ;
            world.setBlock(i + 15, j + 8 , k + 14, Blocks.cobblestone)       ;
            world.setBlock(i + 3 , j + 10, k + 6 , Blocks.cobblestone)       ;
            world.setBlock(i + 9 , j + 6 , k + 15, Blocks.cobblestone)       ;
            world.setBlock(i + 3 , j + 10, k + 8 , Blocks.cobblestone)       ;
            world.setBlock(i + 15, j + 7 , k + 14, Blocks.cobblestone)       ;
            world.setBlock(i + 3 , j + 10, k + 10, Blocks.cobblestone)       ;
            world.setBlock(i + 3 , j + 10, k + 11, Blocks.cobblestone)       ;
            world.setBlock(i + 3 , j + 10, k + 12, Blocks.cobblestone)       ;
            world.setBlock(i + 3 , j + 10, k + 13, Blocks.cobblestone)       ;
            world.setBlock(i + 3 , j + 10, k + 14, Blocks.cobblestone)       ;
            world.setBlock(i + 3 , j + 10, k + 15, Blocks.cobblestone)       ;
            world.setBlock(i + 14, j + 11, k + 4 , Blocks.cobblestone)       ;
            world.setBlock(i + 14, j + 10, k + 15, Blocks.cobblestone)       ;
            world.setBlock(i + 14, j + 10, k + 3 , Blocks.cobblestone)       ;
            world.setBlock(i + 3 , j + 11, k + 5 , Blocks.cobblestone)       ;
            world.setBlock(i + 3 , j + 11, k + 6 , Blocks.cobblestone)       ;
            world.setBlock(i + 3 , j + 11, k + 7 , Blocks.cobblestone)       ;
            world.setBlock(i + 3 , j + 11, k + 8 , Blocks.cobblestone)       ;
            world.setBlock(i + 14, j + 9 , k + 15, Blocks.cobblestone)       ;
            world.setBlock(i + 3 , j + 11, k + 10, Blocks.cobblestone)       ;
            world.setBlock(i + 3 , j + 11, k + 11, Blocks.cobblestone)       ;
            world.setBlock(i + 3 , j + 11, k + 12, Blocks.cobblestone)       ;
            world.setBlock(i + 3 , j + 11, k + 13, Blocks.cobblestone)       ;
            world.setBlock(i + 14, j + 9 , k + 3 , Blocks.cobblestone)       ;
            world.setBlock(i + 14, j + 8 , k + 15, Blocks.cobblestone)       ;
            world.setBlock(i + 14, j + 8 , k + 14, Blocks.cobblestone)       ;
            world.setBlock(i + 15, j + 4 , k + 9 , Blocks.cobblestone)       ;
            world.setBlock(i + 15, j + 4 , k + 8 , Blocks.cobblestone)       ;
            world.setBlock(i + 9 , j + 4 , k + 4 , Blocks.cobblestone)       ;
            world.setBlock(i + 14, j + 8 , k + 13, Blocks.cobblestone)       ;
            world.setBlock(i + 14, j + 8 , k + 10, Blocks.cobblestone)       ;
            world.setBlock(i + 14, j + 8 , k + 4 , Blocks.cobblestone)       ;
            world.setBlock(i + 3 , j + 4 , k + 3 , Blocks.cobblestone)       ;
            world.setBlock(i + 14, j + 7 , k + 15, Blocks.cobblestone)       ;
            world.setBlock(i + 3 , j + 4 , k + 4 , Blocks.cobblestone)       ;
            world.setBlock(i + 14, j + 7 , k + 4 , Blocks.cobblestone)       ;
            world.setBlock(i + 4 , j + 4 , k + 3 , Blocks.cobblestone)       ;
            world.setBlock(i + 4 , j + 4 , k + 4 , Blocks.cobblestone)       ;
            world.setBlock(i + 4 , j + 4 , k + 5 , Blocks.cobblestone)       ;
            world.setBlock(i + 4 , j + 4 , k + 6 , Blocks.cobblestone)       ;
            world.setBlock(i + 4 , j + 4 , k + 7 , Blocks.cobblestone)       ;
            world.setBlock(i + 4 , j + 4 , k + 8 , Blocks.cobblestone)       ;
            world.setBlock(i + 4 , j + 4 , k + 9 , Blocks.cobblestone)       ;
            world.setBlock(i + 15, j + 7 , k + 7 , Blocks.cobblestone)       ;
            world.setBlock(i + 15, j + 8 , k + 9 , Blocks.cobblestone)       ;
            world.setBlock(i + 4 , j + 4 , k + 12, Blocks.cobblestone)       ;
            world.setBlock(i + 4 , j + 4 , k + 13, Blocks.cobblestone)       ;
            world.setBlock(i + 4 , j + 4 , k + 14, Blocks.cobblestone)       ;
            world.setBlock(i + 4 , j + 4 , k + 15, Blocks.cobblestone)       ;
            world.setBlock(i + 4 , j + 5 , k + 3 , Blocks.cobblestone)       ;
            world.setBlock(i + 4 , j + 5 , k + 15, Blocks.cobblestone)       ;
            world.setBlock(i + 4 , j + 6 , k + 3 , Blocks.cobblestone)       ;
            world.setBlock(i + 4 , j + 6 , k + 15, Blocks.cobblestone)       ;
            world.setBlock(i + 14, j + 7 , k + 3 , Blocks.cobblestone)       ;
            world.setBlock(i + 4 , j + 7 , k + 15, Blocks.cobblestone)       ;
            world.setBlock(i + 14, j + 6 , k + 6 , Blocks.cobblestone)       ;
            world.setBlock(i + 14, j + 6 , k + 4 , Blocks.cobblestone)       ;
            world.setBlock(i + 14, j + 6 , k + 3 , Blocks.cobblestone)       ;
            world.setBlock(i + 14, j + 5 , k + 15, Blocks.cobblestone)       ;
            world.setBlock(i + 14, j + 5 , k + 7 , Blocks.cobblestone)       ;
            world.setBlock(i + 14, j + 5 , k + 6 , Blocks.cobblestone)       ;
            world.setBlock(i + 4 , j + 8 , k + 6 , Blocks.cobblestone)       ;
            world.setBlock(i + 4 , j + 8 , k + 7 , Blocks.cobblestone)       ;
            world.setBlock(i + 4 , j + 8 , k + 8 , Blocks.cobblestone)       ;
            world.setBlock(i + 14, j + 5 , k + 5 , Blocks.cobblestone)       ;
            world.setBlock(i + 14, j + 5 , k + 4 , Blocks.cobblestone)       ;
            world.setBlock(i + 4 , j + 8 , k + 11, Blocks.cobblestone)       ;
            world.setBlock(i + 4 , j + 8 , k + 12, Blocks.cobblestone)       ;
            world.setBlock(i + 4 , j + 8 , k + 13, Blocks.cobblestone)       ;
            world.setBlock(i + 4 , j + 8 , k + 14, Blocks.cobblestone)       ;
            world.setBlock(i + 4 , j + 8 , k + 15, Blocks.cobblestone)       ;
            world.setBlock(i + 14, j + 5 , k + 3 , Blocks.cobblestone)       ;
            world.setBlock(i + 14, j + 4 , k + 15, Blocks.cobblestone)       ;
            world.setBlock(i + 14, j + 4 , k + 13, Blocks.cobblestone)       ;
            world.setBlock(i + 14, j + 4 , k + 12, Blocks.cobblestone)       ;
            world.setBlock(i + 14, j + 4 , k + 11, Blocks.cobblestone)       ;
            world.setBlock(i + 14, j + 4 , k + 10, Blocks.cobblestone)       ;
            world.setBlock(i + 4 , j + 9 , k + 3 , Blocks.cobblestone)       ;
            world.setBlock(i + 4 , j + 9 , k + 15, Blocks.cobblestone)       ;
            world.setBlock(i + 3 , j + 5 , k + 14, Blocks.cobblestone)       ;
            world.setBlock(i + 14, j + 4 , k + 8 , Blocks.cobblestone)       ;
            world.setBlock(i + 1 , j + 9 , k + 8 , Blocks.cobblestone)       ;
            world.setBlock(i + 15, j + 9 , k + 6 , Blocks.cobblestone)       ;
            world.setBlock(i + 3 , j + 6 , k + 3 , Blocks.cobblestone)       ;
            world.setBlock(i + 15, j + 6 , k + 15, Blocks.cobblestone)       ;
            world.setBlock(i + 3 , j + 6 , k + 4 , Blocks.cobblestone)       ;
            world.setBlock(i + 14, j + 4 , k + 3 , Blocks.cobblestone)       ;
            world.setBlock(i + 13, j + 12, k + 14, Blocks.cobblestone)       ;
            world.setBlock(i + 13, j + 12, k + 13, Blocks.cobblestone)       ;
            world.setBlock(i + 3 , j + 6 , k + 6 , Blocks.cobblestone)       ;
            world.setBlock(i + 4 , j + 11, k + 4 , Blocks.cobblestone)       ;
            world.setBlock(i + 13, j + 12, k + 12, Blocks.cobblestone)       ;
            world.setBlock(i + 3 , j + 6 , k + 7 , Blocks.cobblestone)       ;
            world.setBlock(i + 13, j + 12, k + 11, Blocks.cobblestone)       ;
            world.setBlock(i + 13, j + 12, k + 10, Blocks.cobblestone)       ;
            world.setBlock(i + 13, j + 12, k + 9 , Blocks.cobblestone)       ;
            world.setBlock(i + 4 , j + 12, k + 5 , Blocks.cobblestone)       ;
            world.setBlock(i + 4 , j + 12, k + 6 , Blocks.cobblestone)       ;
            world.setBlock(i + 3 , j + 6 , k + 10, Blocks.cobblestone)       ;
            world.setBlock(i + 3 , j + 6 , k + 11, Blocks.cobblestone)       ;
            world.setBlock(i + 15, j + 6 , k + 12, Blocks.cobblestone)       ;
            world.setBlock(i + 3 , j + 6 , k + 12, Blocks.cobblestone)       ;
            world.setBlock(i + 4 , j + 12, k + 11, Blocks.cobblestone)       ;
            world.setBlock(i + 4 , j + 12, k + 12, Blocks.cobblestone)       ;
            world.setBlock(i + 4 , j + 12, k + 13, Blocks.cobblestone)       ;
            world.setBlock(i + 3 , j + 6 , k + 14, Blocks.cobblestone)       ;
            world.setBlock(i + 13, j + 12, k + 8 , Blocks.cobblestone)       ;
            world.setBlock(i + 3 , j + 6 , k + 15, Blocks.cobblestone)       ;
            world.setBlock(i + 13, j + 12, k + 6 , Blocks.cobblestone)       ;
            world.setBlock(i + 13, j + 12, k + 5 , Blocks.cobblestone)       ;
            world.setBlock(i + 13, j + 12, k + 4 , Blocks.cobblestone)       ;
            world.setBlock(i + 3 , j + 7 , k + 4 , Blocks.cobblestone)       ;
            world.setBlock(i + 13, j + 11, k + 3 , Blocks.cobblestone)       ;
            world.setBlock(i + 13, j + 10, k + 15, Blocks.cobblestone)       ;
            world.setBlock(i + 13, j + 9 , k + 15, Blocks.cobblestone)       ;
            world.setBlock(i + 13, j + 9 , k + 3 , Blocks.cobblestone)       ;
            world.setBlock(i + 13, j + 8 , k + 15, Blocks.cobblestone)       ;
            world.setBlock(i + 5 , j + 4 , k + 3 , Blocks.cobblestone)       ;
            world.setBlock(i + 5 , j + 4 , k + 4 , Blocks.cobblestone)       ;
            world.setBlock(i + 5 , j + 4 , k + 5 , Blocks.cobblestone)       ;
            world.setBlock(i + 5 , j + 4 , k + 6 , Blocks.cobblestone)       ;
            world.setBlock(i + 5 , j + 4 , k + 7 , Blocks.cobblestone)       ;
            world.setBlock(i + 5 , j + 4 , k + 8 , Blocks.cobblestone)       ;
            world.setBlock(i + 5 , j + 4 , k + 9 , Blocks.cobblestone)       ;
            world.setBlock(i + 13, j + 8 , k + 13, Blocks.cobblestone)       ;
            world.setBlock(i + 5 , j + 4 , k + 11, Blocks.cobblestone)       ;
            world.setBlock(i + 5 , j + 4 , k + 12, Blocks.cobblestone)       ;
            world.setBlock(i + 3 , j + 7 , k + 12, Blocks.cobblestone)       ;
            world.setBlock(i + 15, j + 6 , k + 7 , Blocks.cobblestone)       ;
            world.setBlock(i + 5 , j + 4 , k + 15, Blocks.cobblestone)       ;
            world.setBlock(i + 5 , j + 5 , k + 3 , Blocks.cobblestone)       ;
            world.setBlock(i + 5 , j + 5 , k + 15, Blocks.cobblestone)       ;
            world.setBlock(i + 13, j + 8 , k + 10, Blocks.cobblestone)       ;
            world.setBlock(i + 5 , j + 6 , k + 15, Blocks.cobblestone)       ;
            world.setBlock(i + 5 , j + 7 , k + 3 , Blocks.cobblestone)       ;
            world.setBlock(i + 5 , j + 7 , k + 15, Blocks.cobblestone)       ;
            world.setBlock(i + 15, j + 6 , k + 5 , Blocks.cobblestone)       ;
            world.setBlock(i + 13, j + 8 , k + 9 , Blocks.cobblestone)       ;
            world.setBlock(i + 13, j + 8 , k + 8 , Blocks.cobblestone)       ;
            world.setBlock(i + 5 , j + 8 , k + 3 , Blocks.cobblestone)       ;
            world.setBlock(i + 13, j + 8 , k + 7 , Blocks.cobblestone)       ;
            world.setBlock(i + 5 , j + 8 , k + 5 , Blocks.cobblestone)       ;
            world.setBlock(i + 5 , j + 8 , k + 6 , Blocks.cobblestone)       ;
            world.setBlock(i + 5 , j + 8 , k + 7 , Blocks.cobblestone)       ;
            world.setBlock(i + 3 , j + 8 , k + 5 , Blocks.cobblestone)       ;
            world.setBlock(i + 3 , j + 8 , k + 6 , Blocks.cobblestone)       ;
            world.setBlock(i + 15, j + 8 , k + 15, Blocks.cobblestone)       ;
            world.setBlock(i + 14, j + 12, k + 12, Blocks.cobblestone)       ;
            world.setBlock(i + 10, j + 7 , k + 15, Blocks.cobblestone)       ;
            world.setBlock(i + 13, j + 8 , k + 6 , Blocks.cobblestone)       ;
            world.setBlock(i + 5 , j + 8 , k + 14, Blocks.cobblestone)       ;
            world.setBlock(i + 5 , j + 8 , k + 15, Blocks.cobblestone)       ;
            world.setBlock(i + 13, j + 8 , k + 5 , Blocks.cobblestone)       ;
            world.setBlock(i + 13, j + 8 , k + 4 , Blocks.cobblestone)       ;
            world.setBlock(i + 13, j + 8 , k + 3 , Blocks.cobblestone)       ;
            world.setBlock(i + 3 , j + 8 , k + 11, Blocks.cobblestone)       ;
            world.setBlock(i + 13, j + 7 , k + 3 , Blocks.cobblestone)       ;
            world.setBlock(i + 3 , j + 8 , k + 12, Blocks.cobblestone)       ;
            world.setBlock(i + 5 , j + 9 , k + 3 , Blocks.cobblestone)       ;
            world.setBlock(i + 5 , j + 9 , k + 15, Blocks.cobblestone)       ;
            world.setBlock(i + 3 , j + 8 , k + 13, Blocks.cobblestone)       ;
            world.setBlock(i + 13, j + 6 , k + 15, Blocks.cobblestone)       ;
            world.setBlock(i + 3 , j + 8 , k + 14, Blocks.cobblestone)       ;
            world.setBlock(i + 13, j + 6 , k + 3 , Blocks.cobblestone)       ;
            world.setBlock(i + 3 , j + 8 , k + 15, Blocks.cobblestone)       ;
            world.setBlock(i + 5 , j + 10, k + 3 , Blocks.cobblestone)       ;
            world.setBlock(i + 5 , j + 10, k + 15, Blocks.cobblestone)       ;
            world.setBlock(i + 13, j + 5 , k + 3 , Blocks.cobblestone)       ;
            world.setBlock(i + 14, j + 12, k + 11, Blocks.cobblestone)       ;
            world.setBlock(i + 14, j + 12, k + 10, Blocks.cobblestone)       ;
            world.setBlock(i + 10, j + 9 , k + 3 , Blocks.cobblestone)       ;
            world.setBlock(i + 14, j + 12, k + 9 , Blocks.cobblestone)       ;
            world.setBlock(i + 5 , j + 11, k + 3 , Blocks.cobblestone)       ;
            world.setBlock(i + 5 , j + 11, k + 15, Blocks.cobblestone)       ;
            world.setBlock(i + 9 , j + 9 , k + 3 , Blocks.cobblestone)       ;
            world.setBlock(i + 3 , j + 9 , k + 4 , Blocks.cobblestone)       ;
            world.setBlock(i + 15, j + 9 , k + 10, Blocks.cobblestone)       ;
            world.setBlock(i + 3 , j + 9 , k + 5 , Blocks.cobblestone)       ;
            world.setBlock(i + 5 , j + 12, k + 5 , Blocks.cobblestone)       ;
            world.setBlock(i + 5 , j + 12, k + 6 , Blocks.cobblestone)       ;
            world.setBlock(i + 5 , j + 12, k + 7 , Blocks.cobblestone)       ;
            world.setBlock(i + 5 , j + 12, k + 8 , Blocks.cobblestone)       ;
            world.setBlock(i + 5 , j + 12, k + 9 , Blocks.cobblestone)       ;
            world.setBlock(i + 5 , j + 12, k + 10, Blocks.cobblestone)       ;
            world.setBlock(i + 5 , j + 12, k + 11, Blocks.cobblestone)       ;
            world.setBlock(i + 14, j + 12, k + 8 , Blocks.cobblestone)       ;
            world.setBlock(i + 10, j + 12, k + 7 , Blocks.cobblestone)       ;
            world.setBlock(i + 3 , j + 9 , k + 10, Blocks.cobblestone)       ;
            world.setBlock(i + 15, j + 5 , k + 10, Blocks.cobblestone)       ;
            world.setBlock(i + 10, j + 0 , k + 6 , Blocks.cobblestone)       ;
            world.setBlock(i + 15, j + 11, k + 8 , Blocks.cobblestone)       ;
            world.setBlock(i + 13, j + 4 , k + 12, Blocks.cobblestone)       ;
            world.setBlock(i + 13, j + 4 , k + 11, Blocks.cobblestone)       ;
            world.setBlock(i + 13, j + 4 , k + 10, Blocks.cobblestone)       ;
            world.setBlock(i + 13, j + 4 , k + 9 , Blocks.cobblestone)       ;
            world.setBlock(i + 13, j + 4 , k + 7 , Blocks.cobblestone)       ;
            world.setBlock(i + 13, j + 4 , k + 6 , Blocks.cobblestone)       ;
            world.setBlock(i + 13, j + 4 , k + 5 , Blocks.cobblestone)       ;
            world.setBlock(i + 13, j + 4 , k + 4 , Blocks.cobblestone)       ;
            world.setBlock(i + 13, j + 4 , k + 3 , Blocks.cobblestone)       ;
            world.setBlock(i + 12, j + 12, k + 14, Blocks.cobblestone)       ;
            world.setBlock(i + 6 , j + 0 , k + 6 , Blocks.cobblestone)       ;
            world.setBlock(i + 6 , j + 0 , k + 7 , Blocks.cobblestone)       ;
            world.setBlock(i + 6 , j + 0 , k + 8 , Blocks.cobblestone)       ;
            world.setBlock(i + 6 , j + 0 , k + 9 , Blocks.cobblestone)       ;
            world.setBlock(i + 6 , j + 0 , k + 10, Blocks.cobblestone)       ;
            world.setBlock(i + 6 , j + 0 , k + 11, Blocks.cobblestone)       ;
            world.setBlock(i + 6 , j + 0 , k + 12, Blocks.cobblestone)       ;
            world.setBlock(i + 12, j + 12, k + 13, Blocks.cobblestone)       ;
            world.setBlock(i + 6 , j + 1 , k + 7 , Blocks.cobblestone)       ;
            world.setBlock(i + 6 , j + 1 , k + 8 , Blocks.cobblestone)       ;
            world.setBlock(i + 12, j + 12, k + 12, Blocks.cobblestone)       ;
            world.setBlock(i + 12, j + 12, k + 10, Blocks.cobblestone)       ;
            world.setBlock(i + 6 , j + 1 , k + 11, Blocks.cobblestone)       ;
            world.setBlock(i + 6 , j + 1 , k + 12, Blocks.cobblestone)       ;
            world.setBlock(i + 6 , j + 2 , k + 6 , Blocks.cobblestone)       ;
            world.setBlock(i + 6 , j + 2 , k + 7 , Blocks.cobblestone)       ;
            world.setBlock(i + 6 , j + 2 , k + 8 , Blocks.cobblestone)       ;
            world.setBlock(i + 6 , j + 2 , k + 9 , Blocks.cobblestone)       ;
            world.setBlock(i + 6 , j + 2 , k + 10, Blocks.cobblestone)       ;
            world.setBlock(i + 6 , j + 2 , k + 11, Blocks.cobblestone)       ;
            world.setBlock(i + 6 , j + 2 , k + 12, Blocks.cobblestone)       ;
            world.setBlock(i + 6 , j + 3 , k + 6 , Blocks.cobblestone)       ;
            world.setBlock(i + 6 , j + 3 , k + 7 , Blocks.cobblestone)       ;
            world.setBlock(i + 12, j + 12, k + 9 , Blocks.cobblestone)       ;
            world.setBlock(i + 6 , j + 3 , k + 9 , Blocks.cobblestone)       ;
            world.setBlock(i + 6 , j + 3 , k + 10, Blocks.cobblestone)       ;
            world.setBlock(i + 6 , j + 3 , k + 11, Blocks.cobblestone)       ;
            world.setBlock(i + 6 , j + 3 , k + 12, Blocks.cobblestone)       ;
            world.setBlock(i + 6 , j + 4 , k + 3 , Blocks.cobblestone)       ;
            world.setBlock(i + 6 , j + 4 , k + 4 , Blocks.cobblestone)       ;
            world.setBlock(i + 6 , j + 4 , k + 5 , Blocks.cobblestone)       ;
            world.setBlock(i + 6 , j + 4 , k + 6 , Blocks.cobblestone)       ;
            world.setBlock(i + 12, j + 12, k + 8 , Blocks.cobblestone)       ;
            world.setBlock(i + 12, j + 12, k + 7 , Blocks.cobblestone)       ;
            world.setBlock(i + 6 , j + 4 , k + 9 , Blocks.cobblestone)       ;
            world.setBlock(i + 12, j + 12, k + 5 , Blocks.cobblestone)       ;
            world.setBlock(i + 12, j + 12, k + 4 , Blocks.cobblestone)       ;
            world.setBlock(i + 6 , j + 4 , k + 12, Blocks.cobblestone)       ;
            world.setBlock(i + 6 , j + 4 , k + 13, Blocks.cobblestone)       ;
            world.setBlock(i + 6 , j + 4 , k + 14, Blocks.cobblestone)       ;
            world.setBlock(i + 6 , j + 4 , k + 15, Blocks.cobblestone)       ;
            world.setBlock(i + 6 , j + 5 , k + 3 , Blocks.cobblestone)       ;
            world.setBlock(i + 12, j + 11, k + 15, Blocks.cobblestone)       ;
            world.setBlock(i + 6 , j + 5 , k + 12, Blocks.cobblestone)       ;
            world.setBlock(i + 12, j + 11, k + 3 , Blocks.cobblestone)       ;
            world.setBlock(i + 6 , j + 6 , k + 3 , Blocks.cobblestone)       ;
            world.setBlock(i + 12, j + 10, k + 15, Blocks.cobblestone)       ;
            world.setBlock(i + 6 , j + 6 , k + 12, Blocks.cobblestone)       ;
            world.setBlock(i + 6 , j + 6 , k + 15, Blocks.cobblestone)       ;
            world.setBlock(i + 6 , j + 7 , k + 3 , Blocks.cobblestone)       ;
            world.setBlock(i + 6 , j + 7 , k + 6 , Blocks.cobblestone)       ;
            world.setBlock(i + 6 , j + 7 , k + 12, Blocks.cobblestone)       ;
            world.setBlock(i + 6 , j + 7 , k + 15, Blocks.cobblestone)       ;
            world.setBlock(i + 12, j + 10, k + 3 , Blocks.cobblestone)       ;
            world.setBlock(i + 12, j + 9 , k + 15, Blocks.cobblestone)       ;
            world.setBlock(i + 12, j + 9 , k + 3 , Blocks.cobblestone)       ;
            world.setBlock(i + 6 , j + 8 , k + 3 , Blocks.cobblestone)       ;
            world.setBlock(i + 6 , j + 8 , k + 4 , Blocks.cobblestone)       ;
            world.setBlock(i + 6 , j + 8 , k + 5 , Blocks.cobblestone)       ;
            world.setBlock(i + 6 , j + 8 , k + 6 , Blocks.cobblestone)       ;
            world.setBlock(i + 12, j + 8 , k + 15, Blocks.cobblestone)       ;
            world.setBlock(i + 12, j + 8 , k + 13, Blocks.cobblestone)       ;
            world.setBlock(i + 12, j + 8 , k + 12, Blocks.cobblestone)       ;
            world.setBlock(i + 12, j + 8 , k + 11, Blocks.cobblestone)       ;
            world.setBlock(i + 12, j + 8 , k + 10, Blocks.cobblestone)       ;
            world.setBlock(i + 9 , j + 4 , k + 5 , Blocks.cobblestone)       ;
            world.setBlock(i + 6 , j + 8 , k + 13, Blocks.cobblestone)       ;
            world.setBlock(i + 6 , j + 8 , k + 14, Blocks.cobblestone)       ;
            world.setBlock(i + 6 , j + 8 , k + 15, Blocks.cobblestone)       ;
            world.setBlock(i + 12, j + 8 , k + 9 , Blocks.cobblestone)       ;
            world.setBlock(i + 12, j + 8 , k + 6 , Blocks.cobblestone)       ;
            world.setBlock(i + 12, j + 8 , k + 5 , Blocks.cobblestone)       ;
            world.setBlock(i + 14, j + 8 , k + 3 , Blocks.cobblestone)       ;
            world.setBlock(i + 12, j + 8 , k + 3 , Blocks.cobblestone)       ;
            world.setBlock(i + 12, j + 7 , k + 15, Blocks.cobblestone)       ;
            world.setBlock(i + 6 , j + 9 , k + 3 , Blocks.cobblestone)       ;
            world.setBlock(i + 14, j + 7 , k + 5 , Blocks.cobblestone)       ;
            world.setBlock(i + 6 , j + 9 , k + 12, Blocks.cobblestone)       ;
            world.setBlock(i + 6 , j + 9 , k + 15, Blocks.cobblestone)       ;
            world.setBlock(i + 12, j + 7 , k + 3 , Blocks.cobblestone)       ;
            world.setBlock(i + 12, j + 6 , k + 15, Blocks.cobblestone)       ;
            world.setBlock(i + 12, j + 6 , k + 3 , Blocks.cobblestone)       ;
            world.setBlock(i + 12, j + 5 , k + 15, Blocks.cobblestone)       ;
            world.setBlock(i + 12, j + 5 , k + 3 , Blocks.cobblestone)       ;
            world.setBlock(i + 6 , j + 10, k + 3 , Blocks.cobblestone)       ;
            world.setBlock(i + 6 , j + 10, k + 6 , Blocks.cobblestone)       ;
            world.setBlock(i + 12, j + 4 , k + 15, Blocks.cobblestone)       ;
            world.setBlock(i + 6 , j + 10, k + 15, Blocks.cobblestone)       ;
            world.setBlock(i + 12, j + 4 , k + 14, Blocks.cobblestone)       ;
            world.setBlock(i + 12, j + 4 , k + 12, Blocks.cobblestone)       ;
            world.setBlock(i + 12, j + 4 , k + 11, Blocks.cobblestone)       ;
            world.setBlock(i + 6 , j + 11, k + 3 , Blocks.cobblestone)       ;
            world.setBlock(i + 12, j + 4 , k + 10, Blocks.cobblestone)       ;
            world.setBlock(i + 6 , j + 11, k + 6 , Blocks.cobblestone)       ;
            world.setBlock(i + 4 , j + 4 , k + 10, Blocks.cobblestone)       ;
            world.setBlock(i + 3 , j + 4 , k + 9 , Blocks.cobblestone)       ;
            world.setBlock(i + 6 , j + 11, k + 12, Blocks.cobblestone)       ;
            world.setBlock(i + 4 , j + 4 , k + 11, Blocks.cobblestone)       ;
            world.setBlock(i + 12, j + 4 , k + 9 , Blocks.cobblestone)       ;
            world.setBlock(i + 12, j + 4 , k + 7 , Blocks.cobblestone)       ;
            world.setBlock(i + 12, j + 4 , k + 6 , Blocks.cobblestone)       ;
            world.setBlock(i + 6 , j + 12, k + 4 , Blocks.cobblestone)       ;
            world.setBlock(i + 6 , j + 12, k + 5 , Blocks.cobblestone)       ;
            world.setBlock(i + 12, j + 4 , k + 5 , Blocks.cobblestone)       ;
            world.setBlock(i + 6 , j + 12, k + 7 , Blocks.cobblestone)       ;
            world.setBlock(i + 6 , j + 12, k + 8 , Blocks.cobblestone)       ;
            world.setBlock(i + 12, j + 4 , k + 4 , Blocks.cobblestone)       ;
            world.setBlock(i + 6 , j + 12, k + 10, Blocks.cobblestone)       ;
            world.setBlock(i + 6 , j + 12, k + 11, Blocks.cobblestone)       ;
            world.setBlock(i + 6 , j + 12, k + 12, Blocks.cobblestone)       ;
            world.setBlock(i + 6 , j + 12, k + 13, Blocks.cobblestone)       ;
            world.setBlock(i + 6 , j + 12, k + 14, Blocks.cobblestone)       ;
            world.setBlock(i + 12, j + 4 , k + 3 , Blocks.cobblestone)       ;
            world.setBlock(i + 12, j + 3 , k + 12, Blocks.cobblestone)       ;
            world.setBlock(i + 12, j + 3 , k + 11, Blocks.cobblestone)       ;
            world.setBlock(i + 12, j + 3 , k + 10, Blocks.cobblestone)       ;
            world.setBlock(i + 12, j + 3 , k + 9 , Blocks.cobblestone)       ;
            world.setBlock(i + 12, j + 3 , k + 8 , Blocks.cobblestone)       ;
            world.setBlock(i + 12, j + 3 , k + 7 , Blocks.cobblestone)       ;
            world.setBlock(i + 12, j + 3 , k + 6 , Blocks.cobblestone)       ;
            world.setBlock(i + 12, j + 2 , k + 12, Blocks.cobblestone)       ;
            world.setBlock(i + 12, j + 2 , k + 11, Blocks.cobblestone)       ;
            world.setBlock(i + 12, j + 2 , k + 10, Blocks.cobblestone)       ;
            world.setBlock(i + 12, j + 2 , k + 9 , Blocks.cobblestone)       ;
            world.setBlock(i + 7 , j + 0 , k + 6 , Blocks.cobblestone)       ;
            world.setBlock(i + 12, j + 2 , k + 8 , Blocks.cobblestone)       ;
            world.setBlock(i + 7 , j + 0 , k + 8 , Blocks.cobblestone)       ;
            world.setBlock(i + 7 , j + 0 , k + 9 , Blocks.cobblestone)       ;
            world.setBlock(i + 12, j + 2 , k + 7 , Blocks.cobblestone)       ;
            world.setBlock(i + 12, j + 2 , k + 6 , Blocks.cobblestone)       ;
            world.setBlock(i + 7 , j + 0 , k + 12, Blocks.cobblestone)       ;
            world.setBlock(i + 12, j + 1 , k + 10, Blocks.cobblestone)       ;
            world.setBlock(i + 7 , j + 1 , k + 12, Blocks.cobblestone)       ;
            world.setBlock(i + 7 , j + 2 , k + 6 , Blocks.cobblestone)       ;
            world.setBlock(i + 7 , j + 2 , k + 12, Blocks.cobblestone)       ;
            world.setBlock(i + 7 , j + 3 , k + 6 , Blocks.cobblestone)       ;
            world.setBlock(i + 7 , j + 3 , k + 12, Blocks.cobblestone)       ;
            world.setBlock(i + 7 , j + 4 , k + 3 , Blocks.cobblestone)       ;
            world.setBlock(i + 7 , j + 4 , k + 4 , Blocks.cobblestone)       ;
            world.setBlock(i + 7 , j + 4 , k + 5 , Blocks.cobblestone)       ;
            world.setBlock(i + 12, j + 1 , k + 8 , Blocks.cobblestone)       ;
            world.setBlock(i + 12, j + 1 , k + 7 , Blocks.cobblestone)       ;
            world.setBlock(i + 7 , j + 4 , k + 13, Blocks.cobblestone)       ;
            world.setBlock(i + 7 , j + 4 , k + 14, Blocks.cobblestone)       ;
            world.setBlock(i + 7 , j + 4 , k + 15, Blocks.cobblestone)       ;
            world.setBlock(i + 7 , j + 5 , k + 3 , Blocks.cobblestone)       ;
            world.setBlock(i + 7 , j + 5 , k + 15, Blocks.cobblestone)       ;
            world.setBlock(i + 7 , j + 6 , k + 3 , Blocks.cobblestone)       ;
            world.setBlock(i + 12, j + 0 , k + 12, Blocks.cobblestone)       ;
            world.setBlock(i + 7 , j + 7 , k + 3 , Blocks.cobblestone)       ;
            world.setBlock(i + 7 , j + 7 , k + 15, Blocks.cobblestone)       ;
            world.setBlock(i + 12, j + 0 , k + 11, Blocks.cobblestone)       ;
            world.setBlock(i + 12, j + 0 , k + 10, Blocks.cobblestone)       ;
            world.setBlock(i + 12, j + 0 , k + 9 , Blocks.cobblestone)       ;
            world.setBlock(i + 7 , j + 8 , k + 3 , Blocks.cobblestone)       ;
            world.setBlock(i + 7 , j + 8 , k + 4 , Blocks.cobblestone)       ;
            world.setBlock(i + 7 , j + 8 , k + 5 , Blocks.cobblestone)       ;
            world.setBlock(i + 12, j + 0 , k + 8 , Blocks.cobblestone)       ;
            world.setBlock(i + 12, j + 0 , k + 7 , Blocks.cobblestone)       ;
            world.setBlock(i + 7 , j + 8 , k + 13, Blocks.cobblestone)       ;
            world.setBlock(i + 12, j + 0 , k + 6 , Blocks.cobblestone)       ;
            world.setBlock(i + 7 , j + 8 , k + 15, Blocks.cobblestone)       ;
            world.setBlock(i + 11, j + 12, k + 14, Blocks.cobblestone)       ;
            world.setBlock(i + 11, j + 12, k + 13, Blocks.cobblestone)       ;
            world.setBlock(i + 11, j + 12, k + 12, Blocks.cobblestone)       ;
            world.setBlock(i + 11, j + 12, k + 11, Blocks.cobblestone)       ;
            world.setBlock(i + 14, j + 4 , k + 9 , Blocks.cobblestone)       ;
            world.setBlock(i + 11, j + 12, k + 10, Blocks.cobblestone)       ;
            world.setBlock(i + 7 , j + 9 , k + 3 , Blocks.cobblestone)       ;
            world.setBlock(i + 7 , j + 9 , k + 15, Blocks.cobblestone)       ;
            world.setBlock(i + 14, j + 4 , k + 7 , Blocks.cobblestone)       ;
            world.setBlock(i + 3 , j + 5 , k + 15, Blocks.cobblestone)       ;
            world.setBlock(i + 11, j + 12, k + 9 , Blocks.cobblestone)       ;
            world.setBlock(i + 14, j + 4 , k + 6 , Blocks.cobblestone)       ;
            world.setBlock(i + 14, j + 4 , k + 5 , Blocks.cobblestone)       ;
            world.setBlock(i + 7 , j + 10, k + 3 , Blocks.cobblestone)       ;
            world.setBlock(i + 7 , j + 10, k + 15, Blocks.cobblestone)       ;
            world.setBlock(i + 4 , j + 10, k + 3 , Blocks.cobblestone)       ;
            world.setBlock(i + 14, j + 4 , k + 4 , Blocks.cobblestone)       ;
            world.setBlock(i + 11, j + 12, k + 8 , Blocks.cobblestone)       ;
            world.setBlock(i + 11, j + 12, k + 7 , Blocks.cobblestone)       ;
            world.setBlock(i + 11, j + 12, k + 6 , Blocks.cobblestone)       ;
            world.setBlock(i + 11, j + 12, k + 5 , Blocks.cobblestone)       ;
            world.setBlock(i + 11, j + 12, k + 4 , Blocks.cobblestone)       ;
            world.setBlock(i + 7 , j + 11, k + 15, Blocks.cobblestone)       ;
            world.setBlock(i + 11, j + 11, k + 15, Blocks.cobblestone)       ;
            world.setBlock(i + 11, j + 11, k + 12, Blocks.cobblestone)       ;
            world.setBlock(i + 11, j + 11, k + 6 , Blocks.cobblestone)       ;
            world.setBlock(i + 7 , j + 12, k + 4 , Blocks.cobblestone)       ;
            world.setBlock(i + 7 , j + 12, k + 5 , Blocks.cobblestone)       ;
            world.setBlock(i + 7 , j + 12, k + 6 , Blocks.cobblestone)       ;
            world.setBlock(i + 7 , j + 12, k + 7 , Blocks.cobblestone)       ;
            world.setBlock(i + 7 , j + 12, k + 8 , Blocks.cobblestone)       ;
            world.setBlock(i + 11, j + 10, k + 6 , Blocks.cobblestone)       ;
            world.setBlock(i + 7 , j + 12, k + 10, Blocks.cobblestone)       ;
            world.setBlock(i + 7 , j + 12, k + 11, Blocks.cobblestone)       ;
            world.setBlock(i + 7 , j + 12, k + 12, Blocks.cobblestone)       ;
            world.setBlock(i + 7 , j + 12, k + 13, Blocks.cobblestone)       ;
            world.setBlock(i + 7 , j + 12, k + 14, Blocks.cobblestone)       ;
            world.setBlock(i + 11, j + 10, k + 3 , Blocks.cobblestone)       ;
            world.setBlock(i + 11, j + 9 , k + 15, Blocks.cobblestone)       ;
            world.setBlock(i + 11, j + 9 , k + 6 , Blocks.cobblestone)       ;
            world.setBlock(i + 11, j + 9 , k + 3 , Blocks.cobblestone)       ;
            world.setBlock(i + 11, j + 8 , k + 15, Blocks.cobblestone)       ;
            world.setBlock(i + 11, j + 8 , k + 14, Blocks.cobblestone)       ;
            world.setBlock(i + 4 , j + 12, k + 7 , Blocks.cobblestone)       ;
            world.setBlock(i + 4 , j + 12, k + 8 , Blocks.cobblestone)       ;
            world.setBlock(i + 11, j + 8 , k + 13, Blocks.cobblestone)       ;
            world.setBlock(i + 4 , j + 12, k + 9 , Blocks.cobblestone)       ;
            world.setBlock(i + 11, j + 8 , k + 12, Blocks.cobblestone)       ;
            world.setBlock(i + 11, j + 8 , k + 6 , Blocks.cobblestone)       ;
            world.setBlock(i + 4 , j + 12, k + 10, Blocks.cobblestone)       ;
            world.setBlock(i + 11, j + 8 , k + 5 , Blocks.cobblestone)       ;
            world.setBlock(i + 11, j + 8 , k + 4 , Blocks.cobblestone)       ;
            world.setBlock(i + 8 , j + 0 , k + 6 , Blocks.cobblestone)       ;
            world.setBlock(i + 8 , j + 0 , k + 7 , Blocks.cobblestone)       ;
            world.setBlock(i + 8 , j + 0 , k + 8 , Blocks.cobblestone)       ;
            world.setBlock(i + 8 , j + 0 , k + 9 , Blocks.cobblestone)       ;
            world.setBlock(i + 8 , j + 0 , k + 10, Blocks.cobblestone)       ;
            world.setBlock(i + 8 , j + 0 , k + 11, Blocks.cobblestone)       ;
            world.setBlock(i + 8 , j + 0 , k + 12, Blocks.cobblestone)       ;
            world.setBlock(i + 8 , j + 1 , k + 6 , Blocks.cobblestone)       ;
            world.setBlock(i + 13, j + 12, k + 7 , Blocks.cobblestone)       ;
            world.setBlock(i + 8 , j + 2 , k + 6 , Blocks.cobblestone)       ;
            world.setBlock(i + 8 , j + 2 , k + 12, Blocks.cobblestone)       ;
            world.setBlock(i + 8 , j + 3 , k + 6 , Blocks.cobblestone)       ;
            world.setBlock(i + 8 , j + 3 , k + 12, Blocks.cobblestone)       ;
            world.setBlock(i + 8 , j + 4 , k + 3 , Blocks.cobblestone)       ;
            world.setBlock(i + 8 , j + 4 , k + 4 , Blocks.cobblestone)       ;
            world.setBlock(i + 11, j + 8 , k + 3 , Blocks.cobblestone)       ;
            world.setBlock(i + 11, j + 7 , k + 15, Blocks.cobblestone)       ;
            world.setBlock(i + 13, j + 11, k + 15, Blocks.cobblestone)       ;
            world.setBlock(i + 8 , j + 4 , k + 13, Blocks.cobblestone)       ;
            world.setBlock(i + 8 , j + 4 , k + 14, Blocks.cobblestone)       ;
            world.setBlock(i + 8 , j + 4 , k + 15, Blocks.cobblestone)       ;
            world.setBlock(i + 8 , j + 5 , k + 3 , Blocks.cobblestone)       ;
            world.setBlock(i + 8 , j + 5 , k + 15, Blocks.cobblestone)       ;
            world.setBlock(i + 11, j + 7 , k + 6 , Blocks.cobblestone)       ;
            world.setBlock(i + 8 , j + 6 , k + 15, Blocks.cobblestone)       ;
            world.setBlock(i + 8 , j + 7 , k + 3 , Blocks.cobblestone)       ;
            world.setBlock(i + 8 , j + 7 , k + 15, Blocks.cobblestone)       ;
            world.setBlock(i + 11, j + 7 , k + 3 , Blocks.cobblestone)       ;
            world.setBlock(i + 11, j + 6 , k + 15, Blocks.cobblestone)       ;
            world.setBlock(i + 11, j + 6 , k + 12, Blocks.cobblestone)       ;
            world.setBlock(i + 8 , j + 8 , k + 3 , Blocks.cobblestone)       ;
            world.setBlock(i + 8 , j + 8 , k + 4 , Blocks.cobblestone)       ;
            world.setBlock(i + 11, j + 5 , k + 15, Blocks.cobblestone)       ;
            world.setBlock(i + 11, j + 5 , k + 12, Blocks.cobblestone)       ;
            world.setBlock(i + 11, j + 5 , k + 6 , Blocks.cobblestone)       ;
            world.setBlock(i + 8 , j + 8 , k + 13, Blocks.cobblestone)       ;
            world.setBlock(i + 8 , j + 8 , k + 14, Blocks.cobblestone)       ;
            world.setBlock(i + 8 , j + 8 , k + 15, Blocks.cobblestone)       ;
            world.setBlock(i + 11, j + 5 , k + 3 , Blocks.cobblestone)       ;
            world.setBlock(i + 11, j + 4 , k + 15, Blocks.cobblestone)       ;
            world.setBlock(i + 11, j + 4 , k + 14, Blocks.cobblestone)       ;
            world.setBlock(i + 11, j + 4 , k + 13, Blocks.cobblestone)       ;
            world.setBlock(i + 11, j + 4 , k + 12, Blocks.cobblestone)       ;
            world.setBlock(i + 11, j + 4 , k + 6 , Blocks.cobblestone)       ;
            world.setBlock(i + 8 , j + 9 , k + 3 , Blocks.cobblestone)       ;
            world.setBlock(i + 8 , j + 9 , k + 15, Blocks.cobblestone)       ;
            world.setBlock(i + 11, j + 4 , k + 5 , Blocks.cobblestone)       ;
            world.setBlock(i + 11, j + 4 , k + 4 , Blocks.cobblestone)       ;
            world.setBlock(i + 13, j + 8 , k + 12, Blocks.cobblestone)       ;
            world.setBlock(i + 11, j + 4 , k + 3 , Blocks.cobblestone)       ;
            world.setBlock(i + 11, j + 3 , k + 12, Blocks.cobblestone)       ;
            world.setBlock(i + 5 , j + 4 , k + 14, Blocks.cobblestone)       ;
            world.setBlock(i + 11, j + 3 , k + 11, Blocks.cobblestone)       ;
            world.setBlock(i + 11, j + 3 , k + 10, Blocks.cobblestone)       ;
            world.setBlock(i + 11, j + 3 , k + 8 , Blocks.cobblestone)       ;
            world.setBlock(i + 11, j + 3 , k + 7 , Blocks.cobblestone)       ;
            world.setBlock(i + 8 , j + 11, k + 3 , Blocks.cobblestone)       ;
            world.setBlock(i + 8 , j + 11, k + 15, Blocks.cobblestone)       ;
            world.setBlock(i + 11, j + 3 , k + 6 , Blocks.cobblestone)       ;
            world.setBlock(i + 11, j + 2 , k + 12, Blocks.cobblestone)       ;
            world.setBlock(i + 11, j + 2 , k + 11, Blocks.cobblestone)       ;
            world.setBlock(i + 8 , j + 12, k + 4 , Blocks.cobblestone)       ;
            world.setBlock(i + 8 , j + 12, k + 5 , Blocks.cobblestone)       ;
            world.setBlock(i + 8 , j + 12, k + 6 , Blocks.cobblestone)       ;
            world.setBlock(i + 11, j + 2 , k + 9 , Blocks.cobblestone)       ;
            world.setBlock(i + 8 , j + 12, k + 8 , Blocks.cobblestone)       ;
            world.setBlock(i + 8 , j + 12, k + 9 , Blocks.cobblestone)       ;
            world.setBlock(i + 8 , j + 12, k + 10, Blocks.cobblestone)       ;
            world.setBlock(i + 8 , j + 12, k + 11, Blocks.cobblestone)       ;
            world.setBlock(i + 8 , j + 12, k + 12, Blocks.cobblestone)       ;
            world.setBlock(i + 8 , j + 12, k + 13, Blocks.cobblestone)       ;
            world.setBlock(i + 8 , j + 12, k + 14, Blocks.cobblestone)       ;
            world.setBlock(i + 11, j + 2 , k + 8 , Blocks.cobblestone)       ;
            world.setBlock(i + 11, j + 2 , k + 7 , Blocks.cobblestone)       ;
            world.setBlock(i + 11, j + 2 , k + 6 , Blocks.cobblestone)       ;
            world.setBlock(i + 11, j + 1 , k + 12, Blocks.cobblestone)       ;
            world.setBlock(i + 11, j + 1 , k + 11, Blocks.cobblestone)       ;
            world.setBlock(i + 11, j + 1 , k + 10, Blocks.cobblestone)       ;
            world.setBlock(i + 11, j + 1 , k + 9 , Blocks.cobblestone)       ;
            world.setBlock(i + 11, j + 1 , k + 8 , Blocks.cobblestone)       ;
            world.setBlock(i + 11, j + 1 , k + 7 , Blocks.cobblestone)       ;
            world.setBlock(i + 11, j + 1 , k + 6 , Blocks.cobblestone)       ;
            world.setBlock(i + 5 , j + 8 , k + 8 , Blocks.cobblestone)       ;
            world.setBlock(i + 11, j + 0 , k + 12, Blocks.cobblestone)       ;
            world.setBlock(i + 5 , j + 8 , k + 9 , Blocks.cobblestone)       ;
            world.setBlock(i + 11, j + 0 , k + 11, Blocks.cobblestone)       ;
            world.setBlock(i + 5 , j + 8 , k + 10, Blocks.cobblestone)       ;
            world.setBlock(i + 15, j + 8 , k + 4 , Blocks.cobblestone)       ;
            world.setBlock(i + 5 , j + 8 , k + 11, Blocks.cobblestone)       ;
            world.setBlock(i + 9 , j + 0 , k + 6 , Blocks.cobblestone)       ;
            world.setBlock(i + 9 , j + 0 , k + 7 , Blocks.cobblestone)       ;

            world.setBlock(i + 5 , j + 11, k + 9 , Blocks.air)               ;
            world.setBlock(i + 1 , j + 11, k + 9 , Blocks.air)               ;
            world.setBlock(i + 14, j + 11, k + 9 , Blocks.air)               ;
            world.setBlock(i + 9 , j + 11, k + 9 , Blocks.air)               ;
            world.setBlock(i + 8 , j + 11, k + 9 , Blocks.air)               ;
            world.setBlock(i + 4 , j + 11, k + 9 , Blocks.air)               ;
            world.setBlock(i + 6 , j + 11, k + 9 , Blocks.air)               ;
            world.setBlock(i + 12, j + 11, k + 9 , Blocks.air)               ;
            world.setBlock(i + 11, j + 11, k + 9 , Blocks.air)               ;
            world.setBlock(i + 10, j + 11, k + 9 , Blocks.air         , 0, 3);
            world.setBlock(i + 7 , j + 11, k + 9 , Blocks.air         , 0, 3);
            world.setBlock(i + 13, j + 11, k + 9 , Blocks.air         , 0, 3);
            world.setBlock(i + 8 , j + 11, k + 8 , Blocks.air)               ;
            world.setBlock(i + 6 , j + 11, k + 8 , Blocks.air)               ;
            world.setBlock(i + 11, j + 11, k + 8 , Blocks.air)               ;
            world.setBlock(i + 14, j + 11, k + 8 , Blocks.air)               ;
            world.setBlock(i + 1 , j + 11, k + 8 , Blocks.air)               ;
            world.setBlock(i + 7 , j + 11, k + 8 , Blocks.air)               ;
            world.setBlock(i + 12, j + 11, k + 8 , Blocks.air)               ;
            world.setBlock(i + 5 , j + 11, k + 8 , Blocks.air)               ;
            world.setBlock(i + 4 , j + 11, k + 8 , Blocks.air)               ;
            world.setBlock(i + 9 , j + 11, k + 8 , Blocks.air         , 0, 3);
            world.setBlock(i + 10, j + 11, k + 8 , Blocks.air         , 0, 3);
            world.setBlock(i + 13, j + 11, k + 8 , Blocks.air         , 0, 3);
            world.setBlock(i + 6 , j + 11, k + 7 , Blocks.stone_stairs, 7, 3);
            world.setBlock(i + 11, j + 11, k + 7 , Blocks.stone_stairs, 7, 3);
            world.setBlock(i + 4 , j + 11, k + 7 , Blocks.air)               ;
            world.setBlock(i + 8 , j + 11, k + 7 , Blocks.air)               ;
            world.setBlock(i + 12, j + 11, k + 7 , Blocks.air)               ;
            world.setBlock(i + 5 , j + 11, k + 7 , Blocks.air)               ;
            world.setBlock(i + 9 , j + 11, k + 7 , Blocks.air         , 0, 3);
            world.setBlock(i + 14, j + 11, k + 7 , Blocks.air         , 0, 3);
            world.setBlock(i + 13, j + 11, k + 7 , Blocks.air         , 0, 3);
            world.setBlock(i + 7 , j + 11, k + 7 , Blocks.air         , 0, 3);
            world.setBlock(i + 12, j + 11, k + 6 , Blocks.stone_stairs, 5, 3);
            world.setBlock(i + 7 , j + 11, k + 6 , Blocks.stone_stairs, 5, 3);
            world.setBlock(i + 10, j + 11, k + 6 , Blocks.stone_stairs, 4, 3);
            world.setBlock(i + 5 , j + 11, k + 6 , Blocks.stone_stairs, 4, 3);
            world.setBlock(i + 9 , j + 11, k + 6 , Blocks.air)               ;
            world.setBlock(i + 8 , j + 11, k + 6 , Blocks.air)               ;
            world.setBlock(i + 4 , j + 11, k + 6 , Blocks.air)               ;
            world.setBlock(i + 14, j + 11, k + 6 , Blocks.air)               ;
            world.setBlock(i + 13, j + 11, k + 6 , Blocks.air         , 0, 3);
            world.setBlock(i + 6 , j + 11, k + 5 , Blocks.stone_stairs, 6, 3);
            world.setBlock(i + 11, j + 11, k + 5 , Blocks.stone_stairs, 6, 3);
            world.setBlock(i + 8 , j + 11, k + 5 , Blocks.air)               ;
            world.setBlock(i + 12, j + 11, k + 5 , Blocks.air)               ;
            world.setBlock(i + 10, j + 11, k + 5 , Blocks.air)               ;
            world.setBlock(i + 4 , j + 11, k + 5 , Blocks.air)               ;
            world.setBlock(i + 14, j + 11, k + 5 , Blocks.air)               ;
            world.setBlock(i + 7 , j + 11, k + 5 , Blocks.air         , 0, 3);
            world.setBlock(i + 9 , j + 11, k + 5 , Blocks.air         , 0, 3);
            world.setBlock(i + 5 , j + 11, k + 5 , Blocks.air         , 0, 3);
            world.setBlock(i + 13, j + 11, k + 5 , Blocks.air         , 0, 3);
            world.setBlock(i + 6 , j + 11, k + 4 , Blocks.air)               ;
            world.setBlock(i + 5 , j + 11, k + 4 , Blocks.air)               ;
            world.setBlock(i + 9 , j + 11, k + 4 , Blocks.air)               ;
            world.setBlock(i + 7 , j + 11, k + 4 , Blocks.air)               ;
            world.setBlock(i + 10, j + 11, k + 4 , Blocks.air)               ;
            world.setBlock(i + 12, j + 11, k + 4 , Blocks.air)               ;
            world.setBlock(i + 13, j + 11, k + 4 , Blocks.air)               ;
            world.setBlock(i + 8 , j + 11, k + 4 , Blocks.air)               ;
            world.setBlock(i + 11, j + 11, k + 4 , Blocks.air         , 0, 3);
            world.setBlock(i + 11, j + 11, k + 14, Blocks.air)               ;
            world.setBlock(i + 8 , j + 11, k + 14, Blocks.air)               ;
            world.setBlock(i + 6 , j + 11, k + 14, Blocks.air)               ;
            world.setBlock(i + 12, j + 11, k + 14, Blocks.air)               ;
            world.setBlock(i + 13, j + 11, k + 14, Blocks.air)               ;
            world.setBlock(i + 10, j + 11, k + 14, Blocks.air)               ;
            world.setBlock(i + 5 , j + 11, k + 14, Blocks.air)               ;
            world.setBlock(i + 7 , j + 11, k + 14, Blocks.air)               ;
            world.setBlock(i + 9 , j + 11, k + 14, Blocks.air)               ;
            world.setBlock(i + 6 , j + 11, k + 13, Blocks.stone_stairs, 7, 3);
            world.setBlock(i + 11, j + 11, k + 13, Blocks.stone_stairs, 7, 3);
            world.setBlock(i + 4 , j + 11, k + 13, Blocks.air)               ;
            world.setBlock(i + 10, j + 11, k + 13, Blocks.air)               ;
            world.setBlock(i + 12, j + 11, k + 13, Blocks.air)               ;
            world.setBlock(i + 5 , j + 11, k + 13, Blocks.air)               ;
            world.setBlock(i + 14, j + 11, k + 13, Blocks.air)               ;
            world.setBlock(i + 13, j + 11, k + 13, Blocks.air)               ;
            world.setBlock(i + 7 , j + 11, k + 13, Blocks.air         , 0, 3);
            world.setBlock(i + 8 , j + 11, k + 13, Blocks.air         , 0, 3);
            world.setBlock(i + 9 , j + 11, k + 13, Blocks.air         , 0, 3);
            world.setBlock(i + 7 , j + 11, k + 12, Blocks.stone_stairs, 5, 3);
            world.setBlock(i + 12, j + 11, k + 12, Blocks.stone_stairs, 5, 3);
            world.setBlock(i + 5 , j + 11, k + 12, Blocks.stone_stairs, 4, 3);
            world.setBlock(i + 10, j + 11, k + 12, Blocks.stone_stairs, 4, 3);
            world.setBlock(i + 9 , j + 11, k + 12, Blocks.air)               ;
            world.setBlock(i + 4 , j + 11, k + 12, Blocks.air)               ;
            world.setBlock(i + 13, j + 11, k + 12, Blocks.air)               ;
            world.setBlock(i + 8 , j + 11, k + 12, Blocks.air)               ;
            world.setBlock(i + 14, j + 11, k + 12, Blocks.air)               ;
            world.setBlock(i + 11, j + 11, k + 11, Blocks.stone_stairs, 6, 3);
            world.setBlock(i + 6 , j + 11, k + 11, Blocks.stone_stairs, 6, 3);
            world.setBlock(i + 7 , j + 11, k + 11, Blocks.air)               ;
            world.setBlock(i + 10, j + 11, k + 11, Blocks.air)               ;
            world.setBlock(i + 9 , j + 11, k + 11, Blocks.air)               ;
            world.setBlock(i + 5 , j + 11, k + 11, Blocks.air)               ;
            world.setBlock(i + 12, j + 11, k + 11, Blocks.air)               ;
            world.setBlock(i + 13, j + 11, k + 11, Blocks.air)               ;
            world.setBlock(i + 4 , j + 11, k + 11, Blocks.air)               ;
            world.setBlock(i + 14, j + 11, k + 11, Blocks.air)               ;
            world.setBlock(i + 8 , j + 11, k + 11, Blocks.air         , 0, 3);
            world.setBlock(i + 1 , j + 11, k + 10, Blocks.air)               ;
            world.setBlock(i + 11, j + 11, k + 10, Blocks.air)               ;
            world.setBlock(i + 4 , j + 11, k + 10, Blocks.air)               ;
            world.setBlock(i + 8 , j + 11, k + 10, Blocks.air)               ;
            world.setBlock(i + 9 , j + 11, k + 10, Blocks.air         , 0, 3);
            world.setBlock(i + 14, j + 11, k + 10, Blocks.air         , 0, 3);
            world.setBlock(i + 7 , j + 11, k + 10, Blocks.air         , 0, 3);
            world.setBlock(i + 12, j + 11, k + 10, Blocks.air         , 0, 3);
            world.setBlock(i + 5 , j + 11, k + 10, Blocks.air         , 0, 3);
            world.setBlock(i + 13, j + 11, k + 10, Blocks.air         , 0, 3);
            world.setBlock(i + 6 , j + 11, k + 10, Blocks.air         , 0, 3);
            world.setBlock(i + 10, j + 11, k + 10, Blocks.air         , 0, 3);
            world.setBlock(i + 0 , j + 10, k + 9 , Blocks.air)               ;
            world.setBlock(i + 2 , j + 10, k + 9 , Blocks.air)               ;
            world.setBlock(i + 1 , j + 10, k + 9 , Blocks.air)               ;
            world.setBlock(i + 4 , j + 10, k + 9 , Blocks.air)               ;
            world.setBlock(i + 14, j + 10, k + 9 , Blocks.air         , 0, 3);
            world.setBlock(i + 8 , j + 10, k + 9 , Blocks.air         , 0, 3);
            world.setBlock(i + 11, j + 10, k + 9 , Blocks.air         , 0, 3);
            world.setBlock(i + 13, j + 10, k + 9 , Blocks.air         , 0, 3);
            world.setBlock(i + 9 , j + 10, k + 9 , Blocks.air         , 0, 3);
            world.setBlock(i + 10, j + 10, k + 9 , Blocks.air         , 0, 3);
            world.setBlock(i + 6 , j + 10, k + 9 , Blocks.air         , 0, 3);
            world.setBlock(i + 5 , j + 10, k + 9 , Blocks.air         , 0, 3);
            world.setBlock(i + 7 , j + 10, k + 9 , Blocks.air         , 0, 3);
            world.setBlock(i + 12, j + 10, k + 9 , Blocks.air         , 0, 3);
            world.setBlock(i + 1 , j + 10, k + 8 , Blocks.stone_stairs)      ;
            world.setBlock(i + 4 , j + 10, k + 8 , Blocks.air)               ;
            world.setBlock(i + 0 , j + 10, k + 8 , Blocks.air)               ;
            world.setBlock(i + 13, j + 10, k + 8 , Blocks.air         , 0, 3);
            world.setBlock(i + 8 , j + 10, k + 8 , Blocks.air         , 0, 3);
            world.setBlock(i + 14, j + 10, k + 8 , Blocks.air         , 0, 3);
            world.setBlock(i + 5 , j + 10, k + 8 , Blocks.air         , 0, 3);
            world.setBlock(i + 9 , j + 10, k + 8 , Blocks.air         , 0, 3);
            world.setBlock(i + 7 , j + 10, k + 8 , Blocks.air         , 0, 3);
            world.setBlock(i + 12, j + 10, k + 8 , Blocks.air         , 0, 3);
            world.setBlock(i + 10, j + 10, k + 8 , Blocks.air         , 0, 3);
            world.setBlock(i + 11, j + 10, k + 8 , Blocks.air         , 0, 3);
            world.setBlock(i + 6 , j + 10, k + 8 , Blocks.air         , 0, 3);
            world.setBlock(i + 11, j + 10, k + 7 , Blocks.air)               ;
            world.setBlock(i + 6 , j + 10, k + 7 , Blocks.air)               ;
            world.setBlock(i + 4 , j + 10, k + 7 , Blocks.air)               ;
            world.setBlock(i + 8 , j + 10, k + 7 , Blocks.air         , 0, 3);
            world.setBlock(i + 5 , j + 10, k + 7 , Blocks.air         , 0, 3);
            world.setBlock(i + 13, j + 10, k + 7 , Blocks.air         , 0, 3);
            world.setBlock(i + 9 , j + 10, k + 7 , Blocks.air         , 0, 3);
            world.setBlock(i + 10, j + 10, k + 7 , Blocks.air         , 0, 3);
            world.setBlock(i + 12, j + 10, k + 7 , Blocks.air         , 0, 3);
            world.setBlock(i + 7 , j + 10, k + 7 , Blocks.air         , 0, 3);
            world.setBlock(i + 14, j + 10, k + 7 , Blocks.air         , 0, 3);
            world.setBlock(i + 4 , j + 10, k + 6 , Blocks.air)               ;
            world.setBlock(i + 10, j + 10, k + 6 , Blocks.air)               ;
            world.setBlock(i + 5 , j + 10, k + 6 , Blocks.air)               ;
            world.setBlock(i + 7 , j + 10, k + 6 , Blocks.air)               ;
            world.setBlock(i + 12, j + 10, k + 6 , Blocks.air)               ;
            world.setBlock(i + 13, j + 10, k + 6 , Blocks.air         , 0, 3);
            world.setBlock(i + 9 , j + 10, k + 6 , Blocks.air         , 0, 3);
            world.setBlock(i + 8 , j + 10, k + 6 , Blocks.air         , 0, 3);
            world.setBlock(i + 14, j + 10, k + 6 , Blocks.air         , 0, 3);
            world.setBlock(i + 4 , j + 10, k + 5 , Blocks.air)               ;
            world.setBlock(i + 6 , j + 10, k + 5 , Blocks.air)               ;
            world.setBlock(i + 11, j + 10, k + 5 , Blocks.air)               ;
            world.setBlock(i + 7 , j + 10, k + 5 , Blocks.air         , 0, 3);
            world.setBlock(i + 13, j + 10, k + 5 , Blocks.air         , 0, 3);
            world.setBlock(i + 14, j + 10, k + 5 , Blocks.air         , 0, 3);
            world.setBlock(i + 8 , j + 10, k + 5 , Blocks.air         , 0, 3);
            world.setBlock(i + 12, j + 10, k + 5 , Blocks.air         , 0, 3);
            world.setBlock(i + 5 , j + 10, k + 5 , Blocks.air         , 0, 3);
            world.setBlock(i + 10, j + 10, k + 5 , Blocks.air         , 0, 3);
            world.setBlock(i + 9 , j + 10, k + 5 , Blocks.air         , 0, 3);
            world.setBlock(i + 14, j + 10, k + 4 , Blocks.air)               ;
            world.setBlock(i + 7 , j + 10, k + 4 , Blocks.air)               ;
            world.setBlock(i + 4 , j + 10, k + 4 , Blocks.air)               ;
            world.setBlock(i + 8 , j + 10, k + 4 , Blocks.air         , 0, 3);
            world.setBlock(i + 6 , j + 10, k + 4 , Blocks.air         , 0, 3);
            world.setBlock(i + 13, j + 10, k + 4 , Blocks.air         , 0, 3);
            world.setBlock(i + 12, j + 10, k + 4 , Blocks.air         , 0, 3);
            world.setBlock(i + 5 , j + 10, k + 4 , Blocks.air         , 0, 3);
            world.setBlock(i + 11, j + 10, k + 4 , Blocks.air         , 0, 3);
            world.setBlock(i + 9 , j + 10, k + 4 , Blocks.air         , 0, 3);
            world.setBlock(i + 10, j + 10, k + 4 , Blocks.air         , 0, 3);
            world.setBlock(i + 4 , j + 10, k + 14, Blocks.air)               ;
            world.setBlock(i + 13, j + 10, k + 14, Blocks.air         , 0, 3);
            world.setBlock(i + 5 , j + 10, k + 14, Blocks.air         , 0, 3);
            world.setBlock(i + 9 , j + 10, k + 14, Blocks.air         , 0, 3);
            world.setBlock(i + 12, j + 10, k + 14, Blocks.air         , 0, 3);
            world.setBlock(i + 8 , j + 10, k + 14, Blocks.air         , 0, 3);
            world.setBlock(i + 11, j + 10, k + 14, Blocks.air         , 0, 3);
            world.setBlock(i + 7 , j + 10, k + 14, Blocks.air         , 0, 3);
            world.setBlock(i + 6 , j + 10, k + 14, Blocks.air         , 0, 3);
            world.setBlock(i + 10, j + 10, k + 14, Blocks.air         , 0, 3);
            world.setBlock(i + 6 , j + 10, k + 13, Blocks.air)               ;
            world.setBlock(i + 11, j + 10, k + 13, Blocks.air)               ;
            world.setBlock(i + 4 , j + 10, k + 13, Blocks.air)               ;
            world.setBlock(i + 8 , j + 10, k + 13, Blocks.air         , 0, 3);
            world.setBlock(i + 7 , j + 10, k + 13, Blocks.air         , 0, 3);
            world.setBlock(i + 9 , j + 10, k + 13, Blocks.air         , 0, 3);
            world.setBlock(i + 14, j + 10, k + 13, Blocks.air         , 0, 3);
            world.setBlock(i + 5 , j + 10, k + 13, Blocks.air         , 0, 3);
            world.setBlock(i + 10, j + 10, k + 13, Blocks.air         , 0, 3);
            world.setBlock(i + 13, j + 10, k + 13, Blocks.air         , 0, 3);
            world.setBlock(i + 12, j + 10, k + 13, Blocks.air         , 0, 3);
            world.setBlock(i + 10, j + 10, k + 12, Blocks.air)               ;
            world.setBlock(i + 5 , j + 10, k + 12, Blocks.air)               ;
            world.setBlock(i + 7 , j + 10, k + 12, Blocks.air)               ;
            world.setBlock(i + 12, j + 10, k + 12, Blocks.air)               ;
            world.setBlock(i + 4 , j + 10, k + 12, Blocks.air)               ;
            world.setBlock(i + 13, j + 10, k + 12, Blocks.air         , 0, 3);
            world.setBlock(i + 9 , j + 10, k + 12, Blocks.air         , 0, 3);
            world.setBlock(i + 14, j + 10, k + 12, Blocks.air         , 0, 3);
            world.setBlock(i + 8 , j + 10, k + 12, Blocks.air         , 0, 3);
            world.setBlock(i + 4 , j + 10, k + 11, Blocks.air)               ;
            world.setBlock(i + 11, j + 10, k + 11, Blocks.air)               ;
            world.setBlock(i + 6 , j + 10, k + 11, Blocks.air)               ;
            world.setBlock(i + 9 , j + 10, k + 11, Blocks.air         , 0, 3);
            world.setBlock(i + 10, j + 10, k + 11, Blocks.air         , 0, 3);
            world.setBlock(i + 5 , j + 10, k + 11, Blocks.air         , 0, 3);
            world.setBlock(i + 14, j + 10, k + 11, Blocks.air         , 0, 3);
            world.setBlock(i + 12, j + 10, k + 11, Blocks.air         , 0, 3);
            world.setBlock(i + 8 , j + 10, k + 11, Blocks.air         , 0, 3);
            world.setBlock(i + 13, j + 10, k + 11, Blocks.air         , 0, 3);
            world.setBlock(i + 7 , j + 10, k + 11, Blocks.air         , 0, 3);
            world.setBlock(i + 1 , j + 10, k + 10, Blocks.stone_stairs)      ;
            world.setBlock(i + 0 , j + 10, k + 10, Blocks.air)               ;
            world.setBlock(i + 4 , j + 10, k + 10, Blocks.air)               ;
            world.setBlock(i + 7 , j + 10, k + 10, Blocks.air         , 0, 3);
            world.setBlock(i + 9 , j + 10, k + 10, Blocks.air         , 0, 3);
            world.setBlock(i + 11, j + 10, k + 10, Blocks.air         , 0, 3);
            world.setBlock(i + 13, j + 10, k + 10, Blocks.air         , 0, 3);
            world.setBlock(i + 12, j + 10, k + 10, Blocks.air         , 0, 3);
            world.setBlock(i + 6 , j + 10, k + 10, Blocks.air         , 0, 3);
            world.setBlock(i + 10, j + 10, k + 10, Blocks.air         , 0, 3);
            world.setBlock(i + 5 , j + 10, k + 10, Blocks.air         , 0, 3);
            world.setBlock(i + 14, j + 10, k + 10, Blocks.air         , 0, 3);
            world.setBlock(i + 8 , j + 10, k + 10, Blocks.air         , 0, 3);
            world.setBlock(i + 2 , j + 9 , k + 9 , Blocks.air)               ;
            world.setBlock(i + 4 , j + 9 , k + 9 , Blocks.air)               ;
            world.setBlock(i + 1 , j + 9 , k + 9 , Blocks.air)               ;
            world.setBlock(i + 0 , j + 9 , k + 9 , Blocks.air)               ;
            world.setBlock(i + 12, j + 9 , k + 9 , Blocks.air         , 0, 3);
            world.setBlock(i + 9 , j + 9 , k + 9 , Blocks.air         , 0, 3);
            world.setBlock(i + 13, j + 9 , k + 9 , Blocks.air         , 0, 3);
            world.setBlock(i + 14, j + 9 , k + 9 , Blocks.air         , 0, 3);
            world.setBlock(i + 8 , j + 9 , k + 9 , Blocks.air         , 0, 3);
            world.setBlock(i + 5 , j + 9 , k + 9 , Blocks.air         , 0, 3);
            world.setBlock(i + 7 , j + 9 , k + 9 , Blocks.air         , 0, 3);
            world.setBlock(i + 10, j + 9 , k + 9 , Blocks.air         , 0, 3);
            world.setBlock(i + 11, j + 9 , k + 9 , Blocks.air         , 0, 3);
            world.setBlock(i + 6 , j + 9 , k + 9 , Blocks.air         , 0, 3);
            world.setBlock(i + 0 , j + 9 , k + 8 , Blocks.stone_stairs)      ;
            world.setBlock(i + 4 , j + 9 , k + 8 , Blocks.air)               ;
            world.setBlock(i + 8 , j + 9 , k + 8 , Blocks.air         , 0, 3);
            world.setBlock(i + 9 , j + 9 , k + 8 , Blocks.air         , 0, 3);
            world.setBlock(i + 13, j + 9 , k + 8 , Blocks.air         , 0, 3);
            world.setBlock(i + 6 , j + 9 , k + 8 , Blocks.air         , 0, 3);
            world.setBlock(i + 12, j + 9 , k + 8 , Blocks.air         , 0, 3);
            world.setBlock(i + 11, j + 9 , k + 8 , Blocks.air         , 0, 3);
            world.setBlock(i + 10, j + 9 , k + 8 , Blocks.air         , 0, 3);
            world.setBlock(i + 7 , j + 9 , k + 8 , Blocks.air         , 0, 3);
            world.setBlock(i + 5 , j + 9 , k + 8 , Blocks.air         , 0, 3);
            world.setBlock(i + 14, j + 9 , k + 8 , Blocks.air         , 0, 3);
            world.setBlock(i + 4 , j + 9 , k + 7 , Blocks.air)               ;
            world.setBlock(i + 9 , j + 9 , k + 7 , Blocks.air         , 0, 3);
            world.setBlock(i + 6 , j + 9 , k + 7 , Blocks.air         , 0, 3);
            world.setBlock(i + 12, j + 9 , k + 7 , Blocks.air         , 0, 3);
            world.setBlock(i + 11, j + 9 , k + 7 , Blocks.air         , 0, 3);
            world.setBlock(i + 5 , j + 9 , k + 7 , Blocks.air         , 0, 3);
            world.setBlock(i + 7 , j + 9 , k + 7 , Blocks.air         , 0, 3);
            world.setBlock(i + 8 , j + 9 , k + 7 , Blocks.air         , 0, 3);
            world.setBlock(i + 14, j + 9 , k + 7 , Blocks.air         , 0, 3);
            world.setBlock(i + 10, j + 9 , k + 7 , Blocks.air         , 0, 3);
            world.setBlock(i + 13, j + 9 , k + 7 , Blocks.air         , 0, 3);
            world.setBlock(i + 4 , j + 9 , k + 6 , Blocks.air)               ;
            world.setBlock(i + 12, j + 9 , k + 6 , Blocks.air         , 0, 3);
            world.setBlock(i + 7 , j + 9 , k + 6 , Blocks.air         , 0, 3);
            world.setBlock(i + 13, j + 9 , k + 6 , Blocks.air         , 0, 3);
            world.setBlock(i + 8 , j + 9 , k + 6 , Blocks.air         , 0, 3);
            world.setBlock(i + 9 , j + 9 , k + 6 , Blocks.air         , 0, 3);
            world.setBlock(i + 5 , j + 9 , k + 6 , Blocks.air         , 0, 3);
            world.setBlock(i + 10, j + 9 , k + 6 , Blocks.air         , 0, 3);
            world.setBlock(i + 14, j + 9 , k + 6 , Blocks.air         , 0, 3);
            world.setBlock(i + 4 , j + 9 , k + 5 , Blocks.air)               ;
            world.setBlock(i + 11, j + 9 , k + 5 , Blocks.air         , 0, 3);
            world.setBlock(i + 9 , j + 9 , k + 5 , Blocks.air         , 0, 3);
            world.setBlock(i + 8 , j + 9 , k + 5 , Blocks.air         , 0, 3);
            world.setBlock(i + 10, j + 9 , k + 5 , Blocks.air         , 0, 3);
            world.setBlock(i + 12, j + 9 , k + 5 , Blocks.air         , 0, 3);
            world.setBlock(i + 6 , j + 9 , k + 5 , Blocks.air         , 0, 3);
            world.setBlock(i + 5 , j + 9 , k + 5 , Blocks.air         , 0, 3);
            world.setBlock(i + 13, j + 9 , k + 5 , Blocks.air         , 0, 3);
            world.setBlock(i + 14, j + 9 , k + 5 , Blocks.air         , 0, 3);
            world.setBlock(i + 7 , j + 9 , k + 5 , Blocks.air         , 0, 3);
            world.setBlock(i + 4 , j + 9 , k + 4 , Blocks.air)               ;
            world.setBlock(i + 13, j + 9 , k + 4 , Blocks.air         , 0, 3);
            world.setBlock(i + 7 , j + 9 , k + 4 , Blocks.air         , 0, 3);
            world.setBlock(i + 10, j + 9 , k + 4 , Blocks.air         , 0, 3);
            world.setBlock(i + 6 , j + 9 , k + 4 , Blocks.air         , 0, 3);
            world.setBlock(i + 5 , j + 9 , k + 4 , Blocks.air         , 0, 3);
            world.setBlock(i + 8 , j + 9 , k + 4 , Blocks.air         , 0, 3);
            world.setBlock(i + 12, j + 9 , k + 4 , Blocks.air         , 0, 3);
            world.setBlock(i + 9 , j + 9 , k + 4 , Blocks.air         , 0, 3);
            world.setBlock(i + 11, j + 9 , k + 4 , Blocks.air         , 0, 3);
            world.setBlock(i + 14, j + 9 , k + 4 , Blocks.air         , 0, 3);
            world.setBlock(i + 4 , j + 9 , k + 14, Blocks.air)               ;
            world.setBlock(i + 10, j + 9 , k + 14, Blocks.air         , 0, 3);
            world.setBlock(i + 13, j + 9 , k + 14, Blocks.air         , 0, 3);
            world.setBlock(i + 6 , j + 9 , k + 14, Blocks.air         , 0, 3);
            world.setBlock(i + 5 , j + 9 , k + 14, Blocks.air         , 0, 3);
            world.setBlock(i + 8 , j + 9 , k + 14, Blocks.air         , 0, 3);
            world.setBlock(i + 11, j + 9 , k + 14, Blocks.air         , 0, 3);
            world.setBlock(i + 9 , j + 9 , k + 14, Blocks.air         , 0, 3);
            world.setBlock(i + 12, j + 9 , k + 14, Blocks.air         , 0, 3);
            world.setBlock(i + 7 , j + 9 , k + 14, Blocks.air         , 0, 3);
            world.setBlock(i + 14, j + 9 , k + 14, Blocks.air         , 0, 3);
            world.setBlock(i + 4 , j + 9 , k + 13, Blocks.air)               ;
            world.setBlock(i + 6 , j + 9 , k + 13, Blocks.air         , 0, 3);
            world.setBlock(i + 9 , j + 9 , k + 13, Blocks.air         , 0, 3);
            world.setBlock(i + 5 , j + 9 , k + 13, Blocks.air         , 0, 3);
            world.setBlock(i + 7 , j + 9 , k + 13, Blocks.air         , 0, 3);
            world.setBlock(i + 8 , j + 9 , k + 13, Blocks.air         , 0, 3);
            world.setBlock(i + 13, j + 9 , k + 13, Blocks.air         , 0, 3);
            world.setBlock(i + 12, j + 9 , k + 13, Blocks.air         , 0, 3);
            world.setBlock(i + 10, j + 9 , k + 13, Blocks.air         , 0, 3);
            world.setBlock(i + 11, j + 9 , k + 13, Blocks.air         , 0, 3);
            world.setBlock(i + 14, j + 9 , k + 13, Blocks.air         , 0, 3);
            world.setBlock(i + 4 , j + 9 , k + 12, Blocks.air)               ;
            world.setBlock(i + 14, j + 9 , k + 12, Blocks.air         , 0, 3);
            world.setBlock(i + 5 , j + 9 , k + 12, Blocks.air         , 0, 3);
            world.setBlock(i + 7 , j + 9 , k + 12, Blocks.air         , 0, 3);
            world.setBlock(i + 13, j + 9 , k + 12, Blocks.air         , 0, 3);
            world.setBlock(i + 9 , j + 9 , k + 12, Blocks.air         , 0, 3);
            world.setBlock(i + 10, j + 9 , k + 12, Blocks.air         , 0, 3);
            world.setBlock(i + 8 , j + 9 , k + 12, Blocks.air         , 0, 3);
            world.setBlock(i + 12, j + 9 , k + 12, Blocks.air         , 0, 3);
            world.setBlock(i + 4 , j + 9 , k + 11, Blocks.air)               ;
            world.setBlock(i + 6 , j + 9 , k + 11, Blocks.air)               ;
            world.setBlock(i + 10, j + 9 , k + 11, Blocks.air         , 0, 3);
            world.setBlock(i + 12, j + 9 , k + 11, Blocks.air         , 0, 3);
            world.setBlock(i + 11, j + 9 , k + 11, Blocks.air         , 0, 3);
            world.setBlock(i + 13, j + 9 , k + 11, Blocks.air         , 0, 3);
            world.setBlock(i + 7 , j + 9 , k + 11, Blocks.air         , 0, 3);
            world.setBlock(i + 9 , j + 9 , k + 11, Blocks.air         , 0, 3);
            world.setBlock(i + 14, j + 9 , k + 11, Blocks.air         , 0, 3);
            world.setBlock(i + 5 , j + 9 , k + 11, Blocks.air         , 0, 3);
            world.setBlock(i + 8 , j + 9 , k + 11, Blocks.air         , 0, 3);
            world.setBlock(i + 0 , j + 9 , k + 10, Blocks.stone_stairs)      ;
            world.setBlock(i + 4 , j + 9 , k + 10, Blocks.air)               ;
            world.setBlock(i + 13, j + 9 , k + 10, Blocks.air         , 0, 3);
            world.setBlock(i + 11, j + 9 , k + 10, Blocks.air         , 0, 3);
            world.setBlock(i + 10, j + 9 , k + 10, Blocks.air         , 0, 3);
            world.setBlock(i + 9 , j + 9 , k + 10, Blocks.air         , 0, 3);
            world.setBlock(i + 5 , j + 9 , k + 10, Blocks.air         , 0, 3);
            world.setBlock(i + 14, j + 9 , k + 10, Blocks.air         , 0, 3);
            world.setBlock(i + 12, j + 9 , k + 10, Blocks.air         , 0, 3);
            world.setBlock(i + 6 , j + 9 , k + 10, Blocks.air         , 0, 3);
            world.setBlock(i + 8 , j + 9 , k + 10, Blocks.air         , 0, 3);
            world.setBlock(i + 7 , j + 9 , k + 10, Blocks.air         , 0, 3);
            world.setBlock(i + 6 , j + 8 , k + 9 , Blocks.stone_stairs, 5, 3);
            world.setBlock(i + 11, j + 8 , k + 9 , Blocks.stone_stairs, 4, 3);
            world.setBlock(i + 7 , j + 8 , k + 9 , Blocks.air)               ;
            world.setBlock(i + 9 , j + 8 , k + 9 , Blocks.air         , 0, 3);
            world.setBlock(i + 8 , j + 8 , k + 9 , Blocks.air         , 0, 3);
            world.setBlock(i + 14, j + 8 , k + 9 , Blocks.air         , 0, 3);
            world.setBlock(i + 10, j + 8 , k + 9 , Blocks.air         , 0, 3);
            world.setBlock(i + 6 , j + 8 , k + 8 , Blocks.stone_stairs, 5, 3);
            world.setBlock(i + 11, j + 8 , k + 8 , Blocks.stone_stairs, 4, 3);
            world.setBlock(i + 14, j + 8 , k + 8 , Blocks.air)               ;
            world.setBlock(i + 7 , j + 8 , k + 8 , Blocks.air         , 0, 3);
            world.setBlock(i + 8 , j + 8 , k + 8 , Blocks.air         , 0, 3);
            world.setBlock(i + 9 , j + 8 , k + 8 , Blocks.air         , 0, 3);
            world.setBlock(i + 10, j + 8 , k + 8 , Blocks.air         , 0, 3);
            world.setBlock(i + 6 , j + 8 , k + 7 , Blocks.stone_stairs, 5, 3);
            world.setBlock(i + 11, j + 8 , k + 7 , Blocks.stone_stairs, 4, 3);
            world.setBlock(i + 9 , j + 8 , k + 7 , Blocks.air)               ;
            world.setBlock(i + 10, j + 8 , k + 7 , Blocks.air)               ;
            world.setBlock(i + 8 , j + 8 , k + 7 , Blocks.air)               ;
            world.setBlock(i + 14, j + 8 , k + 7 , Blocks.air)               ;
            world.setBlock(i + 7 , j + 8 , k + 7 , Blocks.air)               ;
            world.setBlock(i + 9 , j + 8 , k + 6 , Blocks.stone_stairs, 7, 3);
            world.setBlock(i + 10, j + 8 , k + 6 , Blocks.stone_stairs, 7, 3);
            world.setBlock(i + 8 , j + 8 , k + 6 , Blocks.stone_stairs, 7, 3);
            world.setBlock(i + 7 , j + 8 , k + 6 , Blocks.stone_stairs, 7, 3);
            world.setBlock(i + 14, j + 8 , k + 6 , Blocks.air         , 0, 3);
            world.setBlock(i + 14, j + 8 , k + 5 , Blocks.stone_stairs, 3, 3);
            world.setBlock(i + 9 , j + 8 , k + 12, Blocks.stone_stairs, 6, 3);
            world.setBlock(i + 8 , j + 8 , k + 12, Blocks.stone_stairs, 6, 3);
            world.setBlock(i + 10, j + 8 , k + 12, Blocks.stone_stairs, 6, 3);
            world.setBlock(i + 7 , j + 8 , k + 12, Blocks.stone_stairs, 6, 3);
            world.setBlock(i + 6 , j + 8 , k + 11, Blocks.stone_stairs, 5, 3);
